Workbook

Sheet Hướng dẫn
A1: Label test tham chiếu cho CUT GitBug-Java (không có test trùng tên)
A3: Mục đích | B3: Với các CUT không có file test tên <Tên>Test / Test<Tên> / <Tên>Tests, xác định test class do người viết nào kiểm thử CUT để dùng làm test tham chiếu (RQ3, mô tả).
A4: Tiêu chí PAIRED (chốt trước khi label) | B4: Chọn PAIRED khi test class (1) nằm trong thư mục test của cùng module tại commit đã fix, (2) viết bằng Java, và (3) có ít nhất một test method gọi trực tiếp API của CUT (tạo đối tượng CUT bằng new, gọi method của CUT, hoặc gọi method static của CUT). Nếu nhiều test class thỏa, chọn test class gọi trực tiếp nhiều API của CUT nhất; hòa thì chọn class có tên chứa tên CUT, rồi đến class cùng package.
A5: Không tính | B5: File *IT (integration test chạy bằng Maven failsafe, thường cần dịch vụ ngoài), file *Example hoặc lớp tiện ích/fake không có test method, và test của class khác chỉ dùng CUT gián tiếp. Khi hai test bằng điểm, ưu tiên unit test chạy bằng surefire.
A6: Tiêu chí NONE | B6: Chọn NONE khi không có test class Java nào thỏa tiêu chí trên: chỉ nhắc tên CUT trong comment hoặc import, chỉ dùng CUT gián tiếp qua class khác, hoặc test viết bằng Groovy/Kotlin.
A7: Không được làm | B7: Không xem bất kỳ kết quả chạy ARROW hay EvoSuite nào khi label. Không chọn CUT 'dễ': label mọi dòng, việc chọn 1 CUT mỗi repository sẽ rút ngẫu nhiên sau đó.
A8: Cách điền (sheet Label) | B8: 1) Mở CUT bằng link ở cột G. 2) Xem các ứng viên trong sheet 'Ứng viên' (lọc cột 'STT CUT' bằng số STT), mở link GitHub để đọc test. 3) Điền cột K = PAIRED hoặc NONE. 4) Nếu PAIRED: điền số hạng ứng viên ở cột L, hoặc dán đường dẫn test khác ở cột M (đường dẫn tính từ gốc repository). Cột N tự hiện test_class_path. 5) Ghi lý do ngắn ở cột O và tên người label ở cột P.
A9: Người kiểm tra | B9: Người thứ hai xem lại (ít nhất các dòng ưu tiên A), ghi tên ở cột Q và Có/Không ở cột R. Dòng 'Không' cần thống nhất lại rồi sửa K–N.
A10: Ô cần điền | B10: Ô nền vàng (cột K–M, O–S). Cột N nền xám là công thức, không sửa.
A11: Ví dụ một dòng | B11: CUT src/main/java/com/ezylang/evalex/parser/Tokenizer.java → K = PAIRED, L = 1 (TokenizerArrayTest.java), O = 'TokenizerArrayTest tạo new Tokenizer(...) và gọi parse() trong mọi test method', P = tên người label.
A12: Ưu tiên | B12: A = repository chưa có CUT nào qua preflight (label xong có thể thêm repository mới). B = repository đã có CUT qua preflight (label để quy tắc áp dụng đồng nhất cho mọi CUT).
A13: Ứng viên được tìm thế nào | B13: Script scripts/analyze_gitbug_test_evidence.py checkout CUT và thư mục test tại commit đã fix, giữ file test nhắc tên CUT mà cùng package, import CUT hoặc dùng tên đầy đủ, rồi đếm số test method (@Test, @ParameterizedTest, …) gọi trực tiếp CUT (new CUT, CUT.x(), biến kiểu CUT gọi method). Xếp hạng theo số test method gọi trực tiếp. Danh sách chỉ là gợi ý; có thể chọn test ngoài danh sách ở cột M.
A14: Sau khi label | B14: Báo lại để chuyển sheet Label thành manual_test_labels.csv, chạy lại normalize_gitbug.py --manual-labels và preflight cho các CUT mới.

Sheet Label
A1: STT | B1: Ưu tiên | C1: Repository | D1: Bug (project_id) | E1: CUT (class_path) | F1: CUT FQN | G1: Mở CUT | H1: Số test đã quét | I1: Số ứng viên | J1: Ứng viên hạng 1 (gợi ý) | K1: Quyết định (PAIRED / NONE) | L1: Chọn ứng viên số (1, 2, …) | M1: Đường dẫn test khác (nếu không có trong ứng viên) | N1: test_class_path (tự tính) | O1: Lý do | P1: Người label | Q1: Người kiểm tra | R1: Kiểm tra đồng ý? (Có / Không) | S1: Ghi chú
A2: 1 | B2: A — repo chưa có CUT qua preflight | C2: Bindambc/whatsapp-business-java-api | D2: Bindambc-whatsapp-business-java-api-362caf5eb33c | E2: src/main/java/com/whatsapp/api/domain/messages/Language.java | F2: com.whatsapp.api.domain.messages.Language | G2: mở | H2: 32 | I2: =COUNTIF('Ứng viên'!$B$2:$B$238,A2) -> 3 | J2: src/test/java/com/whatsapp/api/impl/WhatsappBusinessCloudApiTest.java | K2: PAIRED | L2: 1 | N2: =IF(K2<>"PAIRED","",IF(M2<>"",M2,IF(L2="","",IFERROR(INDEX('Ứng viên'!$D$2:$D$238,MATCH(A2&"-"&L2,'Ứng viên'!$A$2:$A$238,0)),"⚠ số ứng viên không hợp lệ")))) -> src/test/java/com/whatsapp/api/impl/WhatsappBusinessCloudApiTest.java | O2: WhatsappBusinessCloudApiTest.java: 1/14 test method gọi trực tiếp Language (testSendTemplateTextMessage); ví dụ: .setLanguage(new Language(LanguageType.PT_BR))// | P2: dungnthe180616
A3: 2 | B3: A — repo chưa có CUT qua preflight | C3: Bindambc/whatsapp-business-java-api | D3: Bindambc-whatsapp-business-java-api-fd321cb63437 | E3: src/main/java/com/whatsapp/api/domain/templates/QuickReplyButton.java | F3: com.whatsapp.api.domain.templates.QuickReplyButton | G3: mở | H3: 48 | I3: =COUNTIF('Ứng viên'!$B$2:$B$238,A3) -> 4 | J3: src/test/java/com/whatsapp/api/impl/WhatsappBusinessManagementApiTest.java | K3: PAIRED | L3: 1 | N3: =IF(K3<>"PAIRED","",IF(M3<>"",M3,IF(L3="","",IFERROR(INDEX('Ứng viên'!$D$2:$D$238,MATCH(A3&"-"&L3,'Ứng viên'!$A$2:$A$238,0)),"⚠ số ứng viên không hợp lệ")))) -> src/test/java/com/whatsapp/api/impl/WhatsappBusinessManagementApiTest.java | O3: WhatsappBusinessManagementApiTest.java: 4/21 test method gọi trực tiếp QuickReplyButton (testCreateMessageTemplate3, testCreateMessageTemplate4, testCreateMessageTemplateAuthentication); ví dụ: .addButton(new QuickReplyButton("SIM"))// | P3: dungnthe180616
A4: 3 | B4: A — repo chưa có CUT qua preflight | C4: Bindambc/whatsapp-business-java-api | D4: Bindambc-whatsapp-business-java-api-fd321cb63437 | E4: src/main/java/com/whatsapp/api/domain/templates/UrlButton.java | F4: com.whatsapp.api.domain.templates.UrlButton | G4: mở | H4: 48 | I4: =COUNTIF('Ứng viên'!$B$2:$B$238,A4) -> 2 | J4: src/test/java/com/whatsapp/api/impl/WhatsappBusinessManagementApiTest.java | K4: PAIRED | L4: 1 | N4: =IF(K4<>"PAIRED","",IF(M4<>"",M4,IF(L4="","",IFERROR(INDEX('Ứng viên'!$D$2:$D$238,MATCH(A4&"-"&L4,'Ứng viên'!$A$2:$A$238,0)),"⚠ số ứng viên không hợp lệ")))) -> src/test/java/com/whatsapp/api/impl/WhatsappBusinessManagementApiTest.java | O4: WhatsappBusinessManagementApiTest.java: 1/21 test method gọi trực tiếp UrlButton (testCreateMessageTemplateUtility1); ví dụ: .addButton(new UrlButton("Assistir agora")// | P4: dungnthe180616
A5: 4 | B5: A — repo chưa có CUT qua preflight | C5: BrightSpots/rcv | D5: BrightSpots-rcv-688920f27706 | E5: src/main/java/network/brightspots/rcv/Logger.java | F5: network.brightspots.rcv.Logger | G5: mở | H5: 1 | I5: =COUNTIF('Ứng viên'!$B$2:$B$238,A5) -> 1 | J5: src/test/java/network/brightspots/rcv/TabulatorTests.java | K5: NONE | N5: =IF(K5<>"PAIRED","",IF(M5<>"",M5,IF(L5="","",IFERROR(INDEX('Ứng viên'!$D$2:$D$238,MATCH(A5&"-"&L5,'Ứng viên'!$A$2:$A$238,0)),"⚠ số ứng viên không hợp lệ")))) | O5: TabulatorTests.java có nhắc tới Logger nhưng không test method nào gọi trực tiếp Logger (chỉ dùng gián tiếp, qua class khác hoặc làm kiểu dữ liệu). | P5: dungnthe180616
A6: 5 | B6: A — repo chưa có CUT qua preflight | C6: BrightSpots/rcv | D6: BrightSpots-rcv-688920f27706 | E6: src/main/java/network/brightspots/rcv/ResultsWriter.java | F6: network.brightspots.rcv.ResultsWriter | G6: mở | H6: 1 | I6: =COUNTIF('Ứng viên'!$B$2:$B$238,A6) -> 1 | J6: src/test/java/network/brightspots/rcv/TabulatorTests.java | K6: NONE | N6: =IF(K6<>"PAIRED","",IF(M6<>"",M6,IF(L6="","",IFERROR(INDEX('Ứng viên'!$D$2:$D$238,MATCH(A6&"-"&L6,'Ứng viên'!$A$2:$A$238,0)),"⚠ số ứng viên không hợp lệ")))) | O6: TabulatorTests.java có nhắc tới ResultsWriter nhưng không test method nào gọi trực tiếp ResultsWriter (chỉ dùng gián tiếp, qua class khác hoặc làm kiểu dữ liệu). | P6: dungnthe180616
A7: 6 | B7: A — repo chưa có CUT qua preflight | C7: BrightSpots/rcv | D7: BrightSpots-rcv-c80e6272c83a | E7: src/main/java/network/brightspots/rcv/ResultsWriter.java | F7: network.brightspots.rcv.ResultsWriter | G7: mở | H7: 2 | I7: =COUNTIF('Ứng viên'!$B$2:$B$238,A7) -> 1 | J7: src/test/java/network/brightspots/rcv/TabulatorTests.java | K7: NONE | N7: =IF(K7<>"PAIRED","",IF(M7<>"",M7,IF(L7="","",IFERROR(INDEX('Ứng viên'!$D$2:$D$238,MATCH(A7&"-"&L7,'Ứng viên'!$A$2:$A$238,0)),"⚠ số ứng viên không hợp lệ")))) | O7: TabulatorTests.java có nhắc tới ResultsWriter nhưng không test method nào gọi trực tiếp ResultsWriter (chỉ dùng gián tiếp, qua class khác hoặc làm kiểu dữ liệu). | P7: dungnthe180616
A8: 7 | B8: A — repo chưa có CUT qua preflight | C8: IBM/JSONata4Java | D8: IBM-JSONata4Java-1485a41ccf50 | E8: src/main/java/com/api/jsonata4java/expressions/OrderByOperator.java | F8: com.api.jsonata4java.expressions.OrderByOperator | G8: mở | H8: 72 | I8: =COUNTIF('Ứng viên'!$B$2:$B$238,A8) -> 0 | J8: (không tìm thấy test nào nhắc tới CUT) | K8: NONE | N8: =IF(K8<>"PAIRED","",IF(M8<>"",M8,IF(L8="","",IFERROR(INDEX('Ứng viên'!$D$2:$D$238,MATCH(A8&"-"&L8,'Ứng viên'!$A$2:$A$238,0)),"⚠ số ứng viên không hợp lệ")))) | O8: Không có file test nào (trong 72 file đã quét tại commit đã fix) nhắc tới OrderByOperator qua cùng package, import hoặc tên đầy đủ. | P8: dungnthe180616
A9: 8 | B9: A — repo chưa có CUT qua preflight | C9: Moderocky/ByteSkript | D9: Moderocky-ByteSkript-1dce2997df7f | E9: src/main/java/org/byteskript/skript/compiler/DebugSkriptCompiler.java | F9: org.byteskript.skript.compiler.DebugSkriptCompiler | G9: mở | H9: 11 | I9: =COUNTIF('Ứng viên'!$B$2:$B$238,A9) -> 1 | J9: src/test/java/org/byteskript/skript/test/SyntaxTreeTest.java | K9: PAIRED | L9: 1 | N9: =IF(K9<>"PAIRED","",IF(M9<>"",M9,IF(L9="","",IFERROR(INDEX('Ứng viên'!$D$2:$D$238,MATCH(A9&"-"&L9,'Ứng viên'!$A$2:$A$238,0)),"⚠ số ứng viên không hợp lệ")))) -> src/test/java/org/byteskript/skript/test/SyntaxTreeTest.java | O9: SyntaxTreeTest.java: 1/1 test method gọi trực tiếp DebugSkriptCompiler (testRecompile); ví dụ: final Skript skript = new Skript(new DebugSkriptCompiler(stream)); | P9: dungnthe180616
A10: 9 | B10: A — repo chưa có CUT qua preflight | C10: Netflix/frigga | D10: Netflix-frigga-126b52a55863 | E10: src/main/java/com/netflix/frigga/ami/AppVersion.java | F10: com.netflix.frigga.ami.AppVersion | G10: mở | H10: 8 | I10: =COUNTIF('Ứng viên'!$B$2:$B$238,A10) -> 1 | J10: src/test/groovy/com/netflix/frigga/ami/AppVersionTest.groovy | K10: NONE | N10: =IF(K10<>"PAIRED","",IF(M10<>"",M10,IF(L10="","",IFERROR(INDEX('Ứng viên'!$D$2:$D$238,MATCH(A10&"-"&L10,'Ứng viên'!$A$2:$A$238,0)),"⚠ số ứng viên không hợp lệ")))) | O10: Chỉ có test groovy (AppVersionTest.groovy); tiêu chí yêu cầu test Java. | P10: dungnthe180616
A11: 10 | B11: A — repo chưa có CUT qua preflight | C11: YehiaFarghaly/database-engine | D11: YehiaFarghaly-database-engine-8314bfdec0aa | E11: src/main/java/util/validation/Validator.java | F11: util.validation.Validator | G11: mở | H11: 1 | I11: =COUNTIF('Ứng viên'!$B$2:$B$238,A11) -> 0 | J11: (không tìm thấy test nào nhắc tới CUT) | K11: NONE | N11: =IF(K11<>"PAIRED","",IF(M11<>"",M11,IF(L11="","",IFERROR(INDEX('Ứng viên'!$D$2:$D$238,MATCH(A11&"-"&L11,'Ứng viên'!$A$2:$A$238,0)),"⚠ số ứng viên không hợp lệ")))) | O11: Không có file test nào (trong 1 file đã quét tại commit đã fix) nhắc tới Validator qua cùng package, import hoặc tên đầy đủ. | P11: dungnthe180616
A12: 11 | B12: A — repo chưa có CUT qua preflight | C12: YehiaFarghaly/database-engine | D12: YehiaFarghaly-database-engine-c5f961f27373 | E12: src/main/java/util/validation/Validator.java | F12: util.validation.Validator | G12: mở | H12: 1 | I12: =COUNTIF('Ứng viên'!$B$2:$B$238,A12) -> 0 | J12: (không tìm thấy test nào nhắc tới CUT) | K12: NONE | N12: =IF(K12<>"PAIRED","",IF(M12<>"",M12,IF(L12="","",IFERROR(INDEX('Ứng viên'!$D$2:$D$238,MATCH(A12&"-"&L12,'Ứng viên'!$A$2:$A$238,0)),"⚠ số ứng viên không hợp lệ")))) | O12: Không có file test nào (trong 1 file đã quét tại commit đã fix) nhắc tới Validator qua cùng package, import hoặc tên đầy đủ. | P12: dungnthe180616
A13: 12 | B13: A — repo chưa có CUT qua preflight | C13: assertj/assertj-vavr | D13: assertj-assertj-vavr-f4d7f276e87c | E13: src/main/java/org/assertj/vavr/api/AbstractSeqAssert.java | F13: org.assertj.vavr.api.AbstractSeqAssert | G13: mở | H13: 137 | I13: =COUNTIF('Ứng viên'!$B$2:$B$238,A13) -> 0 | J13: (không tìm thấy test nào nhắc tới CUT) | K13: NONE | N13: =IF(K13<>"PAIRED","",IF(M13<>"",M13,IF(L13="","",IFERROR(INDEX('Ứng viên'!$D$2:$D$238,MATCH(A13&"-"&L13,'Ứng viên'!$A$2:$A$238,0)),"⚠ số ứng viên không hợp lệ")))) | O13: Không có file test nào (trong 137 file đã quét tại commit đã fix) nhắc tới AbstractSeqAssert qua cùng package, import hoặc tên đầy đủ. | P13: dungnthe180616
A14: 13 | B14: A — repo chưa có CUT qua preflight | C14: beanshell/beanshell | D14: beanshell-beanshell-7a60a06bb567 | E14: src/main/java/bsh/This.java | F14: bsh.This | G14: mở | H14: 72 | I14: =COUNTIF('Ứng viên'!$B$2:$B$238,A14) -> 6 | J14: src/test/java/bsh/InterpreterConcurrencyTest.java | K14: PAIRED | L14: 1 | N14: =IF(K14<>"PAIRED","",IF(M14<>"",M14,IF(L14="","",IFERROR(INDEX('Ứng viên'!$D$2:$D$238,MATCH(A14&"-"&L14,'Ứng viên'!$A$2:$A$238,0)),"⚠ số ứng viên không hợp lệ")))) -> src/test/java/bsh/InterpreterConcurrencyTest.java | O14: InterpreterConcurrencyTest.java: 4/4 test method gọi trực tiếp This (single_threaded, multi_threaded_callable, multi_threaded_class_generation_garbage_collected); ví dụ: assertEquals("foo", callable.invokeMethod("call", new Object[] { "foo" }));. Chọn file này vì nhiều test method gọi trực tiếp nhất trong 2 file thỏa tiêu chí | P14: dungnthe180616
A15: 14 | B15: A — repo chưa có CUT qua preflight | C15: beanshell/beanshell | D15: beanshell-beanshell-f345606a29bd | E15: src/main/java/bsh/Operators.java | F15: bsh.Operators | G15: mở | H15: 72 | I15: =COUNTIF('Ứng viên'!$B$2:$B$238,A15) -> 0 | J15: (không tìm thấy test nào nhắc tới CUT) | K15: NONE | N15: =IF(K15<>"PAIRED","",IF(M15<>"",M15,IF(L15="","",IFERROR(INDEX('Ứng viên'!$D$2:$D$238,MATCH(A15&"-"&L15,'Ứng viên'!$A$2:$A$238,0)),"⚠ số ứng viên không hợp lệ")))) | O15: Không có file test nào (trong 72 file đã quét tại commit đã fix) nhắc tới Operators qua cùng package, import hoặc tên đầy đủ. | P15: dungnthe180616
A16: 15 | B16: A — repo chưa có CUT qua preflight | C16: bhlangonijr/chesslib | D16: bhlangonijr-chesslib-cf68677eac6d | E16: src/main/java/com/github/bhlangonijr/chesslib/pgn/GameLoader.java | F16: com.github.bhlangonijr.chesslib.pgn.GameLoader | G16: mở | H16: 10 | I16: =COUNTIF('Ứng viên'!$B$2:$B$238,A16) -> 0 | J16: (không tìm thấy test nào nhắc tới CUT) | K16: NONE | N16: =IF(K16<>"PAIRED","",IF(M16<>"",M16,IF(L16="","",IFERROR(INDEX('Ứng viên'!$D$2:$D$238,MATCH(A16&"-"&L16,'Ứng viên'!$A$2:$A$238,0)),"⚠ số ứng viên không hợp lệ")))) | O16: Không có file test nào (trong 10 file đã quét tại commit đã fix) nhắc tới GameLoader qua cùng package, import hoặc tên đầy đủ. | P16: dungnthe180616
A17: 16 | B17: A — repo chưa có CUT qua preflight | C17: cdimascio/dotenv-java | D17: cdimascio-dotenv-java-bbfbcfa63e3a | E17: src/main/java/io/github/cdimascio/dotenv/internal/DotenvParser.java | F17: io.github.cdimascio.dotenv.internal.DotenvParser | G17: mở | H17: 2 | I17: =COUNTIF('Ứng viên'!$B$2:$B$238,A17) -> 0 | J17: (không tìm thấy test nào nhắc tới CUT) | K17: NONE | N17: =IF(K17<>"PAIRED","",IF(M17<>"",M17,IF(L17="","",IFERROR(INDEX('Ứng viên'!$D$2:$D$238,MATCH(A17&"-"&L17,'Ứng viên'!$A$2:$A$238,0)),"⚠ số ứng viên không hợp lệ")))) | O17: Không có file test nào (trong 2 file đã quét tại commit đã fix) nhắc tới DotenvParser qua cùng package, import hoặc tên đầy đủ. | P17: dungnthe180616
A18: 17 | B18: A — repo chưa có CUT qua preflight | C18: cloudsimplus/cloudsimplus | D18: cloudsimplus-cloudsimplus-61c8b942d1ec | E18: src/main/java/org/cloudsimplus/hosts/HostAbstract.java | F18: org.cloudsimplus.hosts.HostAbstract | G18: mở | H18: 57 | I18: =COUNTIF('Ứng viên'!$B$2:$B$238,A18) -> 0 | J18: (không tìm thấy test nào nhắc tới CUT) | K18: NONE | N18: =IF(K18<>"PAIRED","",IF(M18<>"",M18,IF(L18="","",IFERROR(INDEX('Ứng viên'!$D$2:$D$238,MATCH(A18&"-"&L18,'Ứng viên'!$A$2:$A$238,0)),"⚠ số ứng viên không hợp lệ")))) | O18: Không có file test nào (trong 57 file đã quét tại commit đã fix) nhắc tới HostAbstract qua cùng package, import hoặc tên đầy đủ. | P18: dungnthe180616
A19: 18 | B19: A — repo chưa có CUT qua preflight | C19: crowdin/crowdin-api-client-java | D19: crowdin-crowdin-api-client-java-f0f22b2b56d7 | E19: src/main/java/com/crowdin/client/core/http/impl/json/JacksonJsonTransformer.java | F19: com.crowdin.client.core.http.impl.json.JacksonJsonTransformer | G19: mở | H19: 29 | I19: =COUNTIF('Ứng viên'!$B$2:$B$238,A19) -> 1 | J19: src/test/java/com/crowdin/client/framework/TestHttpClient.java | K19: NONE | N19: =IF(K19<>"PAIRED","",IF(M19<>"",M19,IF(L19="","",IFERROR(INDEX('Ứng viên'!$D$2:$D$238,MATCH(A19&"-"&L19,'Ứng viên'!$A$2:$A$238,0)),"⚠ số ứng viên không hợp lệ")))) | O19: Chỉ có file không chứa test method (TestHttpClient.java), ví dụ file Example hoặc lớp hỗ trợ. | P19: dungnthe180616
A20: 19 | B20: A — repo chưa có CUT qua preflight | C20: ezylang/EvalEx | D20: ezylang-EvalEx-7c39c5478a39 | E20: src/main/java/com/ezylang/evalex/parser/Tokenizer.java | F20: com.ezylang.evalex.parser.Tokenizer | G20: mở | H20: 60 | I20: =COUNTIF('Ứng viên'!$B$2:$B$238,A20) -> 10 | J20: src/test/java/com/ezylang/evalex/parser/TokenizerArrayTest.java | K20: PAIRED | L20: 1 | N20: =IF(K20<>"PAIRED","",IF(M20<>"",M20,IF(L20="","",IFERROR(INDEX('Ứng viên'!$D$2:$D$238,MATCH(A20&"-"&L20,'Ứng viên'!$A$2:$A$238,0)),"⚠ số ứng viên không hợp lệ")))) -> src/test/java/com/ezylang/evalex/parser/TokenizerArrayTest.java | O20: TokenizerArrayTest.java: 9/11 test method gọi trực tiếp Tokenizer (testMissingClosingArray, testUnexpectedClosingArray, testOpenArrayNotAllowedBeginning); ví dụ: assertThatThrownBy(() -> new Tokenizer("a[2+4", configuration).parse()). Chọn file này vì nhiều test method gọi trực tiếp nhất trong 9 file thỏa tiêu chí | P20: dungnthe180616
A21: 20 | B21: A — repo chưa có CUT qua preflight | C21: giraud/reasonml-idea-plugin | D21: giraud-reasonml-idea-plugin-11d991db162a | E21: src/main/java/com/reason/ide/structure/StructureViewElement.java | F21: com.reason.ide.structure.StructureViewElement | G21: mở | H21: 184 | I21: =COUNTIF('Ứng viên'!$B$2:$B$238,A21) -> 0 | J21: (không tìm thấy test nào nhắc tới CUT) | K21: NONE | N21: =IF(K21<>"PAIRED","",IF(M21<>"",M21,IF(L21="","",IFERROR(INDEX('Ứng viên'!$D$2:$D$238,MATCH(A21&"-"&L21,'Ứng viên'!$A$2:$A$238,0)),"⚠ số ứng viên không hợp lệ")))) | O21: Không có file test nào (trong 184 file đã quét tại commit đã fix) nhắc tới StructureViewElement qua cùng package, import hoặc tên đầy đủ. | P21: dungnthe180616
A22: 21 | B22: A — repo chưa có CUT qua preflight | C22: giraud/reasonml-idea-plugin | D22: giraud-reasonml-idea-plugin-11d991db162a | E22: src/main/java/com/reason/lang/core/psi/impl/RPsiModuleSignature.java | F22: com.reason.lang.core.psi.impl.RPsiModuleSignature | G22: mở | H22: 184 | I22: =COUNTIF('Ứng viên'!$B$2:$B$238,A22) -> 3 | J22: src/test/java/com/reason/lang/ocaml/ModuleParsingTest.java | K22: PAIRED | L22: 1 | N22: =IF(K22<>"PAIRED","",IF(M22<>"",M22,IF(L22="","",IFERROR(INDEX('Ứng viên'!$D$2:$D$238,MATCH(A22&"-"&L22,'Ứng viên'!$A$2:$A$238,0)),"⚠ số ứng viên không hợp lệ")))) -> src/test/java/com/reason/lang/ocaml/ModuleParsingTest.java | O22: ModuleParsingTest.java: 13/15 test method gọi trực tiếp RPsiModuleSignature (test_empty, test_alias, test_alias_path); ví dụ: assertEquals("M", e.getName()); | P22: dungnthe180616
A23: 22 | B23: A — repo chưa có CUT qua preflight | C23: giraud/reasonml-idea-plugin | D23: giraud-reasonml-idea-plugin-11d991db162a | E23: src/main/java/com/reason/lang/ocaml/OclParser.java | F23: com.reason.lang.ocaml.OclParser | G23: mở | H23: 184 | I23: =COUNTIF('Ứng viên'!$B$2:$B$238,A23) -> 0 | J23: (không tìm thấy test nào nhắc tới CUT) | K23: NONE | N23: =IF(K23<>"PAIRED","",IF(M23<>"",M23,IF(L23="","",IFERROR(INDEX('Ứng viên'!$D$2:$D$238,MATCH(A23&"-"&L23,'Ứng viên'!$A$2:$A$238,0)),"⚠ số ứng viên không hợp lệ")))) | O23: Không có file test nào (trong 184 file đã quét tại commit đã fix) nhắc tới OclParser qua cùng package, import hoặc tên đầy đủ. | P23: dungnthe180616
A24: 23 | B24: A — repo chưa có CUT qua preflight | C24: giraud/reasonml-idea-plugin | D24: giraud-reasonml-idea-plugin-69749af01bcf | E24: src/main/java/com/reason/lang/ocaml/OclParser.java | F24: com.reason.lang.ocaml.OclParser | G24: mở | H24: 184 | I24: =COUNTIF('Ứng viên'!$B$2:$B$238,A24) -> 0 | J24: (không tìm thấy test nào nhắc tới CUT) | K24: NONE | N24: =IF(K24<>"PAIRED","",IF(M24<>"",M24,IF(L24="","",IFERROR(INDEX('Ứng viên'!$D$2:$D$238,MATCH(A24&"-"&L24,'Ứng viên'!$A$2:$A$238,0)),"⚠ số ứng viên không hợp lệ")))) | O24: Không có file test nào (trong 184 file đã quét tại commit đã fix) nhắc tới OclParser qua cùng package, import hoặc tên đầy đủ. | P24: dungnthe180616
A25: 24 | B25: A — repo chưa có CUT qua preflight | C25: giraud/reasonml-idea-plugin | D25: giraud-reasonml-idea-plugin-f665f0fc21e6 | E25: src/main/java/com/reason/lang/rescript/ResParser.java | F25: com.reason.lang.rescript.ResParser | G25: mở | H25: 183 | I25: =COUNTIF('Ứng viên'!$B$2:$B$238,A25) -> 0 | J25: (không tìm thấy test nào nhắc tới CUT) | K25: NONE | N25: =IF(K25<>"PAIRED","",IF(M25<>"",M25,IF(L25="","",IFERROR(INDEX('Ứng viên'!$D$2:$D$238,MATCH(A25&"-"&L25,'Ứng viên'!$A$2:$A$238,0)),"⚠ số ứng viên không hợp lệ")))) | O25: Không có file test nào (trong 183 file đã quét tại commit đã fix) nhắc tới ResParser qua cùng package, import hoặc tên đầy đủ. | P25: dungnthe180616
A26: 25 | B26: A — repo chưa có CUT qua preflight | C26: gitbucket/markedj | D26: gitbucket-markedj-2dce74e12083 | E26: src/main/java/io/github/gitbucket/markedj/Grammer.java | F26: io.github.gitbucket.markedj.Grammer | G26: mở | H26: 1 | I26: =COUNTIF('Ứng viên'!$B$2:$B$238,A26) -> 0 | J26: (không tìm thấy test nào nhắc tới CUT) | K26: NONE | N26: =IF(K26<>"PAIRED","",IF(M26<>"",M26,IF(L26="","",IFERROR(INDEX('Ứng viên'!$D$2:$D$238,MATCH(A26&"-"&L26,'Ứng viên'!$A$2:$A$238,0)),"⚠ số ứng viên không hợp lệ")))) | O26: Không có file test nào (trong 1 file đã quét tại commit đã fix) nhắc tới Grammer qua cùng package, import hoặc tên đầy đủ. | P26: dungnthe180616
A27: 26 | B27: A — repo chưa có CUT qua preflight | C27: jitterted/ensembler | D27: jitterted-ensembler-14a39138787f | E27: src/main/java/com/jitterted/mobreg/domain/Ensemble.java | F27: com.jitterted.mobreg.domain.Ensemble | G27: mở | H27: 67 | I27: =COUNTIF('Ứng viên'!$B$2:$B$238,A27) -> 37 | J27: src/test/java/com/jitterted/mobreg/domain/EnsembleMemberStatusTest.java | K27: PAIRED | L27: 1 | N27: =IF(K27<>"PAIRED","",IF(M27<>"",M27,IF(L27="","",IFERROR(INDEX('Ứng viên'!$D$2:$D$238,MATCH(A27&"-"&L27,'Ứng viên'!$A$2:$A$238,0)),"⚠ số ứng viên không hợp lệ")))) -> src/test/java/com/jitterted/mobreg/domain/EnsembleMemberStatusTest.java | O27: EnsembleMemberStatusTest.java: 13/13 test method gọi trực tiếp Ensemble (unknownMemberAndPastEnsembleThenStatusHidden, unknownMemberAndFutureEnsembleAndHasSpaceThenStatusUnknown, unknownMemberAndFutureEnsembleAndIsFullThenStatusFull); ví dụ: assertThat(pastEnsemble.statusFor(memberId, startDateTime.plusHours(3))) // duration defaults to 1h55m, so 3 h. Chọn file này vì nhiều test method gọi trực tiếp nhất trong 26 file thỏa tiêu chí | P27: dungnthe180616
A28: 27 | B28: A — repo chưa có CUT qua preflight | C28: jitterted/ensembler | D28: jitterted-ensembler-60ec3bf0273b | E28: src/main/java/com/jitterted/mobreg/domain/Ensemble.java | F28: com.jitterted.mobreg.domain.Ensemble | G28: mở | H28: 67 | I28: =COUNTIF('Ứng viên'!$B$2:$B$238,A28) -> 37 | J28: src/test/java/com/jitterted/mobreg/domain/EnsembleMemberStatusTest.java | K28: PAIRED | L28: 1 | N28: =IF(K28<>"PAIRED","",IF(M28<>"",M28,IF(L28="","",IFERROR(INDEX('Ứng viên'!$D$2:$D$238,MATCH(A28&"-"&L28,'Ứng viên'!$A$2:$A$238,0)),"⚠ số ứng viên không hợp lệ")))) -> src/test/java/com/jitterted/mobreg/domain/EnsembleMemberStatusTest.java | O28: EnsembleMemberStatusTest.java: 13/13 test method gọi trực tiếp Ensemble (unknownMemberAndPastEnsembleThenStatusHidden, unknownMemberAndFutureEnsembleAndHasSpaceThenStatusUnknown, unknownMemberAndFutureEnsembleAndIsFullThenStatusFull); ví dụ: assertThat(pastEnsemble.statusFor(memberId, startDateTime.plusHours(3))) // duration defaults to 1h55m, so 3 h. Chọn file này vì nhiều test method gọi trực tiếp nhất trong 26 file thỏa tiêu chí | P28: dungnthe180616
A29: 28 | B29: A — repo chưa có CUT qua preflight | C29: jitterted/ensembler | D29: jitterted-ensembler-6207c9d46460 | E29: src/main/java/com/jitterted/mobreg/domain/Ensemble.java | F29: com.jitterted.mobreg.domain.Ensemble | G29: mở | H29: 67 | I29: =COUNTIF('Ứng viên'!$B$2:$B$238,A29) -> 37 | J29: src/test/java/com/jitterted/mobreg/domain/EnsembleMemberStatusTest.java | K29: PAIRED | L29: 1 | N29: =IF(K29<>"PAIRED","",IF(M29<>"",M29,IF(L29="","",IFERROR(INDEX('Ứng viên'!$D$2:$D$238,MATCH(A29&"-"&L29,'Ứng viên'!$A$2:$A$238,0)),"⚠ số ứng viên không hợp lệ")))) -> src/test/java/com/jitterted/mobreg/domain/EnsembleMemberStatusTest.java | O29: EnsembleMemberStatusTest.java: 13/13 test method gọi trực tiếp Ensemble (unknownMemberAndPastEnsembleThenStatusHidden, unknownMemberAndFutureEnsembleAndHasSpaceThenStatusUnknown, unknownMemberAndFutureEnsembleAndIsFullThenStatusFull); ví dụ: assertThat(pastEnsemble.statusFor(memberId, startDateTime.plusHours(3))) // duration defaults to 1h55m, so 3 h. Chọn file này vì nhiều test method gọi trực tiếp nhất trong 26 file thỏa tiêu chí | P29: dungnthe180616
A30: 29 | B30: A — repo chưa có CUT qua preflight | C30: semver4j/semver4j | D30: semver4j-semver4j-beb7e5d466c7 | E30: src/main/java/org/semver4j/internal/range/processor/XRangeProcessor.java | F30: org.semver4j.internal.range.processor.XRangeProcessor | G30: mở | H30: 9 | I30: =COUNTIF('Ứng viên'!$B$2:$B$238,A30) -> 0 | J30: (không tìm thấy test nào nhắc tới CUT) | K30: NONE | N30: =IF(K30<>"PAIRED","",IF(M30<>"",M30,IF(L30="","",IFERROR(INDEX('Ứng viên'!$D$2:$D$238,MATCH(A30&"-"&L30,'Ứng viên'!$A$2:$A$238,0)),"⚠ số ứng viên không hợp lệ")))) | O30: Không có file test nào (trong 9 file đã quét tại commit đã fix) nhắc tới XRangeProcessor qua cùng package, import hoặc tên đầy đủ. | P30: dungnthe180616
A31: 30 | B31: A — repo chưa có CUT qua preflight | C31: slub/urnlib | D31: slub-urnlib-106be8d1b804 | E31: src/main/java/de/slub/urn/RQF_RFC8141.java | F31: de.slub.urn.RQF_RFC8141 | G31: mở | H31: 17 | I31: =COUNTIF('Ứng viên'!$B$2:$B$238,A31) -> 2 | J31: src/test/java/de/slub/urn/RFC8141ParserTest.java | K31: PAIRED | L31: 1 | N31: =IF(K31<>"PAIRED","",IF(M31<>"",M31,IF(L31="","",IFERROR(INDEX('Ứng viên'!$D$2:$D$238,MATCH(A31&"-"&L31,'Ứng viên'!$A$2:$A$238,0)),"⚠ số ứng viên không hợp lệ")))) -> src/test/java/de/slub/urn/RFC8141ParserTest.java | O31: RFC8141ParserTest.java: 12/14 test method gọi trực tiếp RQF_RFC8141 (R_component_get_parsed_into_resolution_parameter_map, R_component_can_hold_multiple_parameters, Q_component_get_parsed_into_query_parameter_map); ví dụ: Map<String, String> resolutionParameters = rqf.resolutionParameters();. Chọn file này vì nhiều test method gọi trực tiếp nhất trong 2 file thỏa tiêu chí | P31: dungnthe180616
A32: 31 | B32: A — repo chưa có CUT qua preflight | C32: snowflakedb/snowflake-jdbc | D32: snowflakedb-snowflake-jdbc-002bc9bb528a | E32: src/main/java/net/snowflake/client/jdbc/SnowflakeConnectString.java | F32: net.snowflake.client.jdbc.SnowflakeConnectString | G32: mở | H32: 183 | I32: =COUNTIF('Ứng viên'!$B$2:$B$238,A32) -> 4 | J32: src/test/java/net/snowflake/client/jdbc/ConnectStringParseTest.java | K32: PAIRED | L32: 1 | N32: =IF(K32<>"PAIRED","",IF(M32<>"",M32,IF(L32="","",IFERROR(INDEX('Ứng viên'!$D$2:$D$238,MATCH(A32&"-"&L32,'Ứng viên'!$A$2:$A$238,0)),"⚠ số ứng viên không hợp lệ")))) -> src/test/java/net/snowflake/client/jdbc/ConnectStringParseTest.java | O32: ConnectStringParseTest.java: 2/2 test method gọi trực tiếp SnowflakeConnectString (testParseAccountName, testParseWithIllegalUriCharacters); ví dụ: SnowflakeConnectString cstring = SnowflakeConnectString.parse(jdbcConnectString, info);. Chọn file này vì nhiều test method gọi trực tiếp nhất trong 3 file thỏa tiêu chí | P32: dungnthe180616
A33: 32 | B33: A — repo chưa có CUT qua preflight | C33: snowflakedb/snowflake-jdbc | D33: snowflakedb-snowflake-jdbc-15a45aca6bcd | E33: src/main/java/net/snowflake/client/jdbc/SnowflakeFileTransferAgent.java | F33: net.snowflake.client.jdbc.SnowflakeFileTransferAgent | G33: mở | H33: 189 | I33: =COUNTIF('Ứng viên'!$B$2:$B$238,A33) -> 10 | J33: src/test/java/net/snowflake/client/jdbc/FileUploaderLatestIT.java | K33: PAIRED | L33: 2 | N33: =IF(K33<>"PAIRED","",IF(M33<>"",M33,IF(L33="","",IFERROR(INDEX('Ứng viên'!$D$2:$D$238,MATCH(A33&"-"&L33,'Ứng viên'!$A$2:$A$238,0)),"⚠ số ứng viên không hợp lệ")))) -> src/test/java/net/snowflake/client/jdbc/FileUploaderSessionlessTest.java | O33: FileUploaderSessionlessTest.java: 15/15 test method gọi trực tiếp SnowflakeFileTransferAgent (testGetEncryptionMaterialMissing, testGetEncryptionMaterial, testGetS3StageData); ví dụ: SnowflakeFileTransferAgent.getEncryptionMaterial(. Chọn file này vì nhiều test method gọi trực tiếp nhất trong 3 file thỏa tiêu chí; bỏ qua FileUploaderLatestIT.java vì là integration test (*IT) | P33: dungnthe180616
A34: 33 | B34: A — repo chưa có CUT qua preflight | C34: spring-projects/spring-guice | D34: spring-projects-spring-guice-ce15b8e5802a | E34: src/main/java/org/springframework/guice/module/SpringModule.java | F34: org.springframework.guice.module.SpringModule | G34: mở | H34: 36 | I34: =COUNTIF('Ứng viên'!$B$2:$B$238,A34) -> 7 | J34: src/test/java/org/springframework/guice/module/SpringModuleGuiceBindingAwareTests.java | K34: PAIRED | L34: 1 | N34: =IF(K34<>"PAIRED","",IF(M34<>"",M34,IF(L34="","",IFERROR(INDEX('Ứng viên'!$D$2:$D$238,MATCH(A34&"-"&L34,'Ứng viên'!$A$2:$A$238,0)),"⚠ số ứng viên không hợp lệ")))) -> src/test/java/org/springframework/guice/module/SpringModuleGuiceBindingAwareTests.java | O34: SpringModuleGuiceBindingAwareTests.java: 1/1 test method gọi trực tiếp SpringModule (testAllDependenciesInjectedAndLifeycleMethodsCalledOnce); ví dụ: new SpringModule(BeanFactoryProvider.from(GuiceProjectWithSpringLibraryTestSpringConfig.class)));. Chọn file này vì nhiều test method gọi trực tiếp nhất trong 2 file thỏa tiêu chí | P34: dungnthe180616
A35: 34 | B35: A — repo chưa có CUT qua preflight | C35: st-tu-dresden/salespoint | D35: st-tu-dresden-salespoint-85a764f892aa | E35: src/main/java/org/salespointframework/accountancy/PersistentAccountancy.java | F35: org.salespointframework.accountancy.PersistentAccountancy | G35: mở | H35: 68 | I35: =COUNTIF('Ứng viên'!$B$2:$B$238,A35) -> 0 | J35: (không tìm thấy test nào nhắc tới CUT) | K35: NONE | N35: =IF(K35<>"PAIRED","",IF(M35<>"",M35,IF(L35="","",IFERROR(INDEX('Ứng viên'!$D$2:$D$238,MATCH(A35&"-"&L35,'Ứng viên'!$A$2:$A$238,0)),"⚠ số ứng viên không hợp lệ")))) | O35: Không có file test nào (trong 68 file đã quét tại commit đã fix) nhắc tới PersistentAccountancy qua cùng package, import hoặc tên đầy đủ. | P35: dungnthe180616
A36: 35 | B36: A — repo chưa có CUT qua preflight | C36: vmzakharov/dataframe-ec | D36: vmzakharov-dataframe-ec-12af99192d24 | E36: src/main/java/io/github/vmzakharov/ecdataframe/dsl/value/StringValue.java | F36: io.github.vmzakharov.ecdataframe.dsl.value.StringValue | G36: mở | H36: 65 | I36: =COUNTIF('Ứng viên'!$B$2:$B$238,A36) -> 8 | J36: src/test/java/io/github/vmzakharov/ecdataframe/dsl/ObjectValueCompareOpTest.java | K36: PAIRED | L36: 1 | N36: =IF(K36<>"PAIRED","",IF(M36<>"",M36,IF(L36="","",IFERROR(INDEX('Ứng viên'!$D$2:$D$238,MATCH(A36&"-"&L36,'Ứng viên'!$A$2:$A$238,0)),"⚠ số ứng viên không hợp lệ")))) -> src/test/java/io/github/vmzakharov/ecdataframe/dsl/ObjectValueCompareOpTest.java | O36: ObjectValueCompareOpTest.java: 5/11 test method gọi trực tiếp StringValue (stringEq, stringGt, stringLt); ví dụ: Assert.assertTrue(ExpressionTestUtil.evaluate(ComparisonOp.EQ, new StringValue("Foo"), new StringValue("Foo")). Chọn file này vì nhiều test method gọi trực tiếp nhất trong 8 file thỏa tiêu chí | P36: dungnthe180616
A37: 36 | B37: A — repo chưa có CUT qua preflight | C37: vmzakharov/dataframe-ec | D37: vmzakharov-dataframe-ec-e9eb4dbe0e70 | E37: src/main/java/io/github/vmzakharov/ecdataframe/dataframe/compare/ComparisonResult.java | F37: io.github.vmzakharov.ecdataframe.dataframe.compare.ComparisonResult | G37: mở | H37: 68 | I37: =COUNTIF('Ứng viên'!$B$2:$B$238,A37) -> 0 | J37: (không tìm thấy test nào nhắc tới CUT) | K37: NONE | N37: =IF(K37<>"PAIRED","",IF(M37<>"",M37,IF(L37="","",IFERROR(INDEX('Ứng viên'!$D$2:$D$238,MATCH(A37&"-"&L37,'Ứng viên'!$A$2:$A$238,0)),"⚠ số ứng viên không hợp lệ")))) | O37: Không có file test nào (trong 68 file đã quét tại commit đã fix) nhắc tới ComparisonResult qua cùng package, import hoặc tên đầy đủ. | P37: dungnthe180616
A38: 37 | B38: A — repo chưa có CUT qua preflight | C38: w3c/epubcheck | D38: w3c-epubcheck-0759a82ae407 | E38: src/main/java/com/adobe/epubcheck/opf/OPFChecker30.java | F38: com.adobe.epubcheck.opf.OPFChecker30 | G38: mở | H38: 29 | I38: =COUNTIF('Ứng viên'!$B$2:$B$238,A38) -> 1 | J38: src/test/java/org/w3c/epubcheck/test/ExecutionSteps.java | K38: NONE | N38: =IF(K38<>"PAIRED","",IF(M38<>"",M38,IF(L38="","",IFERROR(INDEX('Ứng viên'!$D$2:$D$238,MATCH(A38&"-"&L38,'Ứng viên'!$A$2:$A$238,0)),"⚠ số ứng viên không hợp lệ")))) | O38: Chỉ có file không chứa test method (ExecutionSteps.java), ví dụ file Example hoặc lớp hỗ trợ. | P38: dungnthe180616
A39: 38 | B39: A — repo chưa có CUT qua preflight | C39: w3c/epubcheck | D39: w3c-epubcheck-0759a82ae407 | E39: src/main/java/com/adobe/epubcheck/ops/OPSHandler30.java | F39: com.adobe.epubcheck.ops.OPSHandler30 | G39: mở | H39: 29 | I39: =COUNTIF('Ứng viên'!$B$2:$B$238,A39) -> 0 | J39: (không tìm thấy test nào nhắc tới CUT) | K39: NONE | N39: =IF(K39<>"PAIRED","",IF(M39<>"",M39,IF(L39="","",IFERROR(INDEX('Ứng viên'!$D$2:$D$238,MATCH(A39&"-"&L39,'Ứng viên'!$A$2:$A$238,0)),"⚠ số ứng viên không hợp lệ")))) | O39: Không có file test nào (trong 29 file đã quét tại commit đã fix) nhắc tới OPSHandler30 qua cùng package, import hoặc tên đầy đủ. | P39: dungnthe180616
A40: 39 | B40: A — repo chưa có CUT qua preflight | C40: w3c/epubcheck | D40: w3c-epubcheck-49aacb238c3e | E40: src/main/java/com/adobe/epubcheck/tool/EpubChecker.java | F40: com.adobe.epubcheck.tool.EpubChecker | G40: mở | H40: 30 | I40: =COUNTIF('Ứng viên'!$B$2:$B$238,A40) -> 0 | J40: (không tìm thấy test nào nhắc tới CUT) | K40: NONE | N40: =IF(K40<>"PAIRED","",IF(M40<>"",M40,IF(L40="","",IFERROR(INDEX('Ứng viên'!$D$2:$D$238,MATCH(A40&"-"&L40,'Ứng viên'!$A$2:$A$238,0)),"⚠ số ứng viên không hợp lệ")))) | O40: Không có file test nào (trong 30 file đã quét tại commit đã fix) nhắc tới EpubChecker qua cùng package, import hoặc tên đầy đủ. | P40: dungnthe180616
...

Sheet Tổng hợp
A1: Tiến độ label
A3: Chỉ số | B3: Giá trị | C3: Cách tính
A4: Tổng số CUT cần label | B4: =COUNTA(Label!$A$2:$A$84) -> 83 | C4: Mọi CUT không có test trùng tên
A5: Đã quyết định | B5: =COUNTIF(Label!$K$2:$K$84,"PAIRED")+COUNTIF(Label!$K$2:$K$84,"NONE") -> 83
A6: PAIRED | B6: =COUNTIF(Label!$K$2:$K$84,"PAIRED") -> 22
A7: NONE | B7: =COUNTIF(Label!$K$2:$K$84,"NONE") -> 61
A8: Chưa label | B8: =B4-B5 -> 0
A9: PAIRED thiếu test_class_path | B9: =COUNTIFS(Label!$K$2:$K$84,"PAIRED",Label!$N$2:$N$84,"")+COUNTIF(Label!$N$2:$N$84,"⚠*") -> 0 | C9: Phải bằng 0 trước khi xuất
A10: Đã có người kiểm tra | B10: =COUNTIF(Label!$R$2:$R$84,"Có")+COUNTIF(Label!$R$2:$R$84,"Không") -> 0
A11: Tỷ lệ đồng ý của người kiểm tra | B11: =IFERROR(COUNTIF(Label!$R$2:$R$84,"Có")/B10,"") | C11: Có / số dòng đã kiểm tra
A12: Repo ưu tiên A có ≥ 1 CUT PAIRED | B12: =SUMPRODUCT((LEFT(Label!$B$2:$B$84,1)="A")*(Label!$K$2:$K$84="PAIRED")/(COUNTIFS(Label!$C$2:$C$84,Label!$C$2:$C$84,Label!$K$2:$K$84,"PAIRED")+(Label!$K$2:$K$84<>"PAIRED"))) -> 10 | C12: Số repo mới có thể đưa vào preflight

Sheet Ứng viên
A1: Khóa (STT-hạng) | B1: STT CUT | C1: Hạng | D1: Test ứng viên (đường dẫn) | E1: Ngôn ngữ | F1: Số test method | G1: Test method gọi trực tiếp CUT | H1: Tên method (tối đa 6) | I1: Cùng package | J1: Dòng ví dụ | K1: Mở trên GitHub
A2: 1-1 | B2: 1 | C2: 1 | D2: src/test/java/com/whatsapp/api/impl/WhatsappBusinessCloudApiTest.java | E2: java | F2: 14 | G2: 1 | H2: testSendTemplateTextMessage | I2: Không | J2: .setLanguage(new Language(LanguageType.PT_BR))// | K2: mở
A3: 1-2 | B3: 1 | C3: 2 | D3: src/test/java/com/whatsapp/api/examples/SendTemplateButtonMessageExample.java | E3: java | F3: 0 | G3: 0 | I3: Không | K3: mở
A4: 1-3 | B4: 1 | C4: 3 | D4: src/test/java/com/whatsapp/api/examples/SendTemplateTextMessageExample.java | E4: java | F4: 0 | G4: 0 | I4: Không | K4: mở
A5: 2-1 | B5: 2 | C5: 1 | D5: src/test/java/com/whatsapp/api/impl/WhatsappBusinessManagementApiTest.java | E5: java | F5: 21 | G5: 4 | H5: testCreateMessageTemplate3, testCreateMessageTemplate4, testCreateMessageTemplateAuthentication, testCreateMessageTemplateMarketing2 | I5: Không | J5: .addButton(new QuickReplyButton("SIM"))// | K5: mở
A6: 2-2 | B6: 2 | C6: 2 | D6: src/test/java/com/whatsapp/api/examples/CreateMessageTemplate3Example.java | E6: java | F6: 0 | G6: 0 | I6: Không | K6: mở
A7: 2-3 | B7: 2 | C7: 3 | D7: src/test/java/com/whatsapp/api/examples/CreateMessageTemplate4Example.java | E7: java | F7: 0 | G7: 0 | I7: Không | K7: mở
A8: 2-4 | B8: 2 | C8: 4 | D8: src/test/java/com/whatsapp/api/examples/CreateMessageTemplate6Example.java | E8: java | F8: 0 | G8: 0 | I8: Không | K8: mở
A9: 3-1 | B9: 3 | C9: 1 | D9: src/test/java/com/whatsapp/api/impl/WhatsappBusinessManagementApiTest.java | E9: java | F9: 21 | G9: 1 | H9: testCreateMessageTemplateUtility1 | I9: Không | J9: .addButton(new UrlButton("Assistir agora")// | K9: mở
A10: 3-2 | B10: 3 | C10: 2 | D10: src/test/java/com/whatsapp/api/examples/CreateMessageTemplate5Example.java | E10: java | F10: 0 | G10: 0 | I10: Không | K10: mở
A11: 4-1 | B11: 4 | C11: 1 | D11: src/test/java/network/brightspots/rcv/TabulatorTests.java | E11: java | F11: 66 | G11: 0 | I11: Có | K11: mở
A12: 5-1 | B12: 5 | C12: 1 | D12: src/test/java/network/brightspots/rcv/TabulatorTests.java | E12: java | F12: 66 | G12: 0 | I12: Có | K12: mở
A13: 6-1 | B13: 6 | C13: 1 | D13: src/test/java/network/brightspots/rcv/TabulatorTests.java | E13: java | F13: 69 | G13: 0 | I13: Có | K13: mở
A14: 8-1 | B14: 8 | C14: 1 | D14: src/test/java/org/byteskript/skript/test/SyntaxTreeTest.java | E14: java | F14: 1 | G14: 1 | H14: testRecompile | I14: Không | J14: final Skript skript = new Skript(new DebugSkriptCompiler(stream)); | K14: mở
A15: 9-1 | B15: 9 | C15: 1 | D15: src/test/groovy/com/netflix/frigga/ami/AppVersionTest.groovy | E15: groovy | F15: 0 | G15: 0 | I15: Có | K15: mở
A16: 13-1 | B16: 13 | C16: 1 | D16: src/test/java/bsh/InterpreterConcurrencyTest.java | E16: java | F16: 4 | G16: 4 | H16: single_threaded, multi_threaded_callable, multi_threaded_class_generation_garbage_collected, multi_threaded_class_generation | I16: Có | J16: assertEquals("foo", callable.invokeMethod("call", new Object[] { "foo" })); | K16: mở
A17: 13-2 | B17: 13 | C17: 2 | D17: src/test/java/bsh/TestBshScriptEngine.java | E17: java | F17: 24 | G17: 2 | H17: test_bsh_script_engine_compile_return_this, test_bsh_script_engine_this_invoke_method | I17: Có | J17: invokeMethod = bshThis.getClass().getMethod("invokeMethod", new Class[] {String.class, Object[].class}); | K17: mở
A18: 13-3 | B18: 13 | C18: 3 | D18: src/test/java/bsh/ReflectTest.java | E18: java | F18: 29 | G18: 0 | I18: Có | K18: mở
A19: 13-4 | B19: 13 | C19: 4 | D19: src/test/java/bsh/PreparsedScriptTest.java | E19: java | F19: 9 | G19: 0 | I19: Có | K19: mở
A20: 13-5 | B20: 13 | C20: 5 | D20: src/test/java/bsh/BshSerializationTest.java | E20: java | F20: 3 | G20: 0 | I20: Có | K20: mở
A21: 13-6 | B21: 13 | C21: 6 | D21: src/test/java/bsh/ConsoleInterfaceTest.java | E21: java | F21: 2 | G21: 0 | I21: Có | K21: mở
A22: 18-1 | B22: 18 | C22: 1 | D22: src/test/java/com/crowdin/client/framework/TestHttpClient.java | E22: java | F22: 0 | G22: 0 | I22: Không | K22: mở
A23: 19-1 | B23: 19 | C23: 1 | D23: src/test/java/com/ezylang/evalex/parser/TokenizerArrayTest.java | E23: java | F23: 11 | G23: 9 | H23: testMissingClosingArray, testUnexpectedClosingArray, testOpenArrayNotAllowedBeginning, testOpenArrayNotAllowedAfterOperator, testOpenArrayNotAllowedAfterBrace, testCloseArrayNotAllowedBeginning | I23: Có | J23: assertThatThrownBy(() -> new Tokenizer("a[2+4", configuration).parse()) | K23: mở
A24: 19-2 | B24: 19 | C24: 2 | D24: src/test/java/com/ezylang/evalex/parser/TokenizerStructureTest.java | E24: java | F24: 9 | G24: 3 | H24: testStructureSeparatorNotAllowedBegin, testStructureSeparatorNotAllowedOperator, testStructureNotAllowed | I24: Có | J24: assertThatThrownBy(() -> new Tokenizer(".", configuration).parse()) | K24: mở
A25: 19-3 | B25: 19 | C25: 3 | D25: src/test/java/com/ezylang/evalex/parser/TokenizerStringLiteralTest.java | E25: java | F25: 11 | G25: 2 | H25: testErrorUnmatchedQuoteStart, testErrorUnmatchedQuoteOffset | I25: Có | J25: assertThatThrownBy(() -> new Tokenizer("\"hello", configuration).parse()) | K25: mở
A26: 19-4 | B26: 19 | C26: 4 | D26: src/test/java/com/ezylang/evalex/parser/TokenizerBracesTest.java | E26: java | F26: 4 | G26: 2 | H26: testMissingClosingBrace, testUnexpectedClosingBrace | I26: Có | J26: assertThatThrownBy(() -> new Tokenizer("(2+4", configuration).parse()) | K26: mở
A27: 19-5 | B27: 19 | C27: 5 | D27: src/test/java/com/ezylang/evalex/parser/TokenizerNumberLiteralTest.java | E27: java | F27: 11 | G27: 1 | H27: testScientificLiteralsParseException | I27: Có | J27: assertThatThrownBy(() -> new Tokenizer(expression, configuration).parse()) | K27: mở
A28: 19-6 | B28: 19 | C28: 6 | D28: src/test/java/com/ezylang/evalex/parser/TokenizerFunctionsTest.java | E28: java | F28: 9 | G28: 1 | H28: testUndefinedFunction | I28: Có | J28: assertThatThrownBy(() -> new Tokenizer("a(b)", configuration).parse()) | K28: mở
A29: 19-7 | B29: 19 | C29: 7 | D29: src/test/java/com/ezylang/evalex/parser/TokenizerPrefixPostfixTest.java | E29: java | F29: 9 | G29: 1 | H29: testPostfixAsPrefixThrowsException | I29: Có | J29: assertThatThrownBy(new Tokenizer("?a", configuration)::parse) | K29: mở
A30: 19-8 | B30: 19 | C30: 8 | D30: src/test/java/com/ezylang/evalex/parser/TokenizerExpressionTest.java | E30: java | F30: 5 | G30: 1 | H30: testUndefinedOperator | I30: Có | J30: assertThatThrownBy(() -> new Tokenizer("a $ b", configuration).parse()) | K30: mở
A31: 19-9 | B31: 19 | C31: 9 | D31: src/test/java/com/ezylang/evalex/parser/TokenizerImplicitMultiplicationTest.java | E31: java | F31: 5 | G31: 1 | H31: testImplicitMultiplicationNotAllowed | I31: Có | J31: assertThatThrownBy(() -> new Tokenizer("2(x+y)", config).parse()) | K31: mở
A32: 19-10 | B32: 19 | C32: 10 | D32: src/test/java/com/ezylang/evalex/parser/BaseParserTest.java | E32: java | F32: 0 | G32: 0 | I32: Có | K32: mở
A33: 21-1 | B33: 21 | C33: 1 | D33: src/test/java/com/reason/lang/ocaml/ModuleParsingTest.java | E33: java | F33: 15 | G33: 13 | H33: test_empty, test_alias, test_alias_path, test_module_type, test_signature_with_constraint, test_module_constraint | I33: Không | J33: assertEquals("M", e.getName()); | K33: mở
A34: 21-2 | B34: 21 | C34: 2 | D34: src/test/java/com/reason/ide/search/reference/ORModuleResolutionPsiGistRMLTest.java | E34: java | F34: 27 | G34: 0 | I34: Không | K34: mở
A35: 21-3 | B35: 21 | C35: 3 | D35: src/test/java/com/reason/ide/search/reference/ORModuleResolutionPsiGistRESTest.java | E35: java | F35: 25 | G35: 0 | I35: Không | K35: mở
A36: 26-1 | B36: 26 | C36: 1 | D36: src/test/java/com/jitterted/mobreg/domain/EnsembleMemberStatusTest.java | E36: java | F36: 13 | G36: 13 | H36: unknownMemberAndPastEnsembleThenStatusHidden, unknownMemberAndFutureEnsembleAndHasSpaceThenStatusUnknown, unknownMemberAndFutureEnsembleAndIsFullThenStatusFull, declinedMemberAndFutureEnsembleAndHasSpaceThenStatusDeclined, declinedMemberAndFutureEnsembleIsFullThenStatusDeclinedFull, acceptedMemberAndPastUncompletedEnsembleThenStatusPendingCompleted | I36: Có | J36: assertThat(pastEnsemble.statusFor(memberId, startDateTime.plusHours(3))) // duration defaults to 1h55m, so 3 hours means it's over | K36: mở
A37: 26-2 | B37: 26 | C37: 2 | D37: src/test/java/com/jitterted/mobreg/domain/EnsembleMembersTest.java | E37: java | F37: 10 | G37: 9 | H37: newEnsembleHasZeroParticipants, joinAsSpectatorEnsembleRemembersTheMember, acceptedMemberWhenJoinAsSpectatorRemovesFromAccepted, declinedMemberWhenJoinAsSpectatorRemovesFromDeclined, spectatorWhenAcceptRemovesFromSpectators, acceptMemberByIdWithEnsembleRemembersTheMember | I37: Có | J37: assertThat(ensemble.acceptedCount()) | K37: mở
A38: 26-3 | B38: 26 | C38: 3 | D38: src/test/java/com/jitterted/mobreg/domain/EnsembleEditTest.java | E38: java | F38: 8 | G38: 8 | H38: canChangeNameForExistingEnsemble, changeNameToNullNotAllowed, canChangeToExistingName, canChangeNameAfterCompleted, canChangeStartDateTime, changeDateTimeToNullNotAllowed | I38: Có | J38: Ensemble before = new Ensemble("before", ZonedDateTime.now()); | K38: mở
A39: 26-4 | B39: 26 | C39: 4 | D39: src/test/java/com/jitterted/mobreg/domain/EnsembleStateTest.java | E39: java | F39: 9 | G39: 7 | H39: newEnsembleIsNotCanceled, newEnsembleIsNotCompleted, whenCompletingEnsembleThenEnsembleIsCompleted, whenCancelingScheduledEnsembleThenEnsembleIsCanceled, canceledEnsembleWhenAcceptMemberThrowsException, completedEnsembleWhenRegisterMemberThrowsException | I39: Có | J39: assertThat(ensemble.isCanceled()) | K39: mở
A40: 26-5 | B40: 26 | C40: 5 | D40: src/test/java/com/jitterted/mobreg/adapter/in/web/admin/AdminDashboardControllerTest.java | E40: java | F40: 6 | G40: 5 | H40: givenOneEnsembleResultsInEnsembleInViewModel, changeExistingEnsembleResultsInChangesSaved, completeEnsembleCompletesTheEnsembleWithRecordingLinkAndRedirects, cancelEnsembleThenEnsembleIsCanceled, manuallyRegisterExistingMemberForEnsemble | I40: Không | J40: ensembleRepository.save(new Ensemble("Name", ZonedDateTime.now())); | K40: mở
...
