Workbook

Sheet Tổng quan
A1: GitBug-Java — kết quả chuẩn hóa và preflight (11/10/2026)
A2: Commit đã fix của mỗi bug, UPSTREAM_PINNED (provenance dataset_record). Số liệu đếm là công thức tham chiếu sheet 'Chi tiết CUT' và 'Loại trước preflight'; ô chữ xanh là số nhập tay từ dữ liệu GitBug-Java.
A4: Bước | B4: Số CUT / file | C4: Số repository | D4: Ghi chú
A5: GitBug-Java gốc (data/bugs/) | B5: 199 | C5: 55 | D5: 199 bug, 55 file JSON mỗi file một repository
A6: File .java trong bug_patch | B6: =COUNTA('Chi tiết CUT'!$A$2:$A$181)+COUNTA('Loại trước preflight'!$D$2:$D$93) -> 272 | D6: Mỗi file Java bị sửa trong bản fix là một ứng viên
A7: Loại: ngoài src/main/java | B7: =COUNTIF('Loại trước preflight'!$D$2:$D$93,"NOT_UNDER_SRC_MAIN_JAVA") -> 9 | C7: 2 | D7: aws/event-ruler, iipc/jwarc
A8: Loại: không có test người viết ghép tên | B8: =COUNTIF('Loại trước preflight'!$D$2:$D$93,"NO_PAIRED_TEST") -> 83 | D8: Quy tắc bắt buộc có test ghép (phương án B)
A9: Đầu vào preflight | B9: =COUNTA('Chi tiết CUT'!$A$2:$A$181) -> 180 | C9: =COUNTA(Repository!$A$2:$A$36) -> 35 | D9: Mọi CUT có test tham chiếu
A10: ELIGIBLE — preflight lần 1 | B10: =COUNTIF('Chi tiết CUT'!$I$2:$I$181,"ELIGIBLE") -> 96 | C10: =SUMPRODUCT(('Chi tiết CUT'!$I$2:$I$181="ELIGIBLE")/COUNTIFS('Chi tiết CUT'!$B$2:$B$181,'Chi tiết CUT'!$B$2:$B$181,'Chi tiết CUT'!$I$2:$I$181,'Chi tiết CUT'!$I$2:$I$181)) -> 17 | D10: Probe gốc của công cụ
A11: ELIGIBLE — sau khi sửa probe và chạy lại | B11: =COUNTIF('Chi tiết CUT'!$L$2:$L$181,"ELIGIBLE") -> 152 | C11: =SUMPRODUCT(('Chi tiết CUT'!$L$2:$L$181="ELIGIBLE")/COUNTIFS('Chi tiết CUT'!$B$2:$B$181,'Chi tiết CUT'!$B$2:$B$181,'Chi tiết CUT'!$L$2:$L$181,'Chi tiết CUT'!$L$2:$L$181)) -> 25 | D11: Chạy lại các CUT không ELIGIBLE/EXCLUDED bằng scripts/rerun_fixed_probe.py
A12: Repository có ≥ 2 bug ELIGIBLE (nguồn pilot) | C12: =Repository!G37 -> 8 | D12: Report 2 cần 10 repository khác nhau cho pilot
A14: Ghi chú
A15: 1. Lần 1: preflight gốc (runs/gitbug-full-20261011). Lần chạy lại: runs/gitbug-rerun-20261011, kết quả gộp ở merged/.
A16: 2. Bản sửa khi chạy lại (không sửa code preflight/, áp dụng lúc chạy qua scripts/rerun_fixed_probe.py): (1) probe khai báo throws Throwable; ép kiểu null theo tham số khi method bị overload, chép import của CUT; (2) module nhắm Java 8 nhưng dùng --release thì build bằng JDK 11; (3) compile probe Maven bỏ qua checkstyle, spring-javaformat, spotless, formatter, jacoco.
A17: 3. Preflight của GitBug-Java vì vậy dùng probe mới hơn bản đã dùng cho Classes2Test; cần ghi vào change log.
A18: 4. Tập đánh giá lấy mỗi repository 1 CUT, nên số CUT tối đa của GitBug-Java bằng số repository ELIGIBLE.

Sheet Chi tiết CUT
A1: task_id | B1: Repository | C1: Bug (commit đã fix) | D1: Class path (CUT) | E1: Test tham chiếu | F1: Build tool | G1: Test framework | H1: JDK dùng khi build | I1: Trạng thái lần 1 | J1: Lý do lần 1 | K1: Chạy lại? | L1: Trạng thái cuối | M1: Lý do cuối | N1: Commit đầy đủ
A2: AuthMe-ConfigMe-7bf10c513479_5db35da89b9d8088 | B2: AuthMe/ConfigMe | C2: 7bf10c513479 | D2: src/main/java/ch/jalu/configme/configurationdata/PropertyListBuilder.java | E2: src/test/java/ch/jalu/configme/configurationdata/PropertyListBuilderTest.java | F2: maven | G2: junit5 | H2: 17.0.20.1 | I2: ELIGIBLE | K2: Không | L2: ELIGIBLE | N2: 7bf10c51347958ead6d2d8d11e6077dbc35c980e
A3: AuthMe-ConfigMe-aa91a6b315ec_ae60ceb030e8d3fc | B3: AuthMe/ConfigMe | C3: aa91a6b315ec | D3: src/main/java/ch/jalu/configme/configurationdata/CommentsConfiguration.java | E3: src/test/java/ch/jalu/configme/configurationdata/CommentsConfigurationTest.java | F3: maven | G3: junit5 | H3: 17.0.20.1 | I3: ELIGIBLE | K3: Không | L3: ELIGIBLE | N3: aa91a6b315ec1ca94780459cc9d697218aea24cb
A4: BrightSpots-rcv-076f75e2417a_2b1bec9a8ff4845c | B4: BrightSpots/rcv | C4: 076f75e2417a | D4: src/main/java/network/brightspots/rcv/Tabulator.java | E4: src/test/java/network/brightspots/rcv/TabulatorTests.java | F4: gradle | G4: unknown | H4: 17.0.20.1 | I4: DEPENDENCY_UNAVAILABLE | J4: DEPENDENCY_UNAVAILABLE | K4: Có | L4: DEPENDENCY_UNAVAILABLE | M4: DEPENDENCY_UNAVAILABLE | N4: 076f75e2417ac2001171f51f359dfcd15d71ee66
A5: Enigmatis-graphql-java-annotations-183752ce8b9a_aa479a5d22a9e951 | B5: Enigmatis/graphql-java-annotations | C5: 183752ce8b9a | D5: src/main/java/graphql/annotations/processor/retrievers/fieldBuilders/DirectivesBuilder.java | E5: src/test/java/graphql/annotations/processor/retrievers/fieldBuilders/DirectivesBuilderTest.java | F5: gradle | G5: unknown | H5: 17.0.20.1 | I5: JDK_UNSUPPORTED | J5: JDK_UNSUPPORTED | K5: Có | L5: JDK_UNSUPPORTED | M5: JDK_UNSUPPORTED | N5: 183752ce8b9ab64dfd43b0679336b28faf7c03b9
A6: GoSimpleLLC-nbvcxz-ee8d5c62f4fb_5dc5ff0d56e066ac | B6: GoSimpleLLC/nbvcxz | C6: ee8d5c62f4fb | D6: src/main/java/me/gosimple/nbvcxz/matching/DictionaryMatcher.java | E6: src/test/java/me/gosimple/nbvcxz/matching/DictionaryMatcherTest.java | F6: maven | G6: junit4 | H6: 17.0.20.1 | I6: ELIGIBLE | K6: Không | L6: ELIGIBLE | N6: ee8d5c62f4fbba1b975a1e8675abb5dff3ef4cb6
A7: LMAX-Exchange-Simple-DSL-7d81cd9e2951_e8167ea0b2c73a87 | B7: LMAX-Exchange/Simple-DSL | C7: 7d81cd9e2951 | D7: src/main/java/com/lmax/simpledsl/internal/DslParamsParser.java | E7: src/test/java/com/lmax/simpledsl/internal/DslParamsParserTest.java | F7: gradle | G7: junit5 | H7: 1.8.0_504 | I7: ELIGIBLE | K7: Không | L7: ELIGIBLE | N7: 7d81cd9e2951eb4c90243f62d92b4f365a16fbc1
A8: LMAX-Exchange-Simple-DSL-81182e58bd80_e74e99fe1e0db330 | B8: LMAX-Exchange/Simple-DSL | C8: 81182e58bd80 | D8: src/main/java/com/lmax/simpledsl/internal/DslParamsParser.java | E8: src/test/java/com/lmax/simpledsl/internal/DslParamsParserTest.java | F8: gradle | G8: junit5 | H8: 1.8.0_504 | I8: ELIGIBLE | K8: Không | L8: ELIGIBLE | N8: 81182e58bd8036e09ac7cea8c169ec427133d0eb
A9: TheAlgorithms-Java-4f1514980495_c7254d933a173a38 | B9: TheAlgorithms/Java | C9: 4f1514980495 | D9: src/main/java/com/thealgorithms/maths/FindMin.java | E9: src/test/java/com/thealgorithms/maths/FindMinTest.java | F9: maven | G9: junit5 | H9: 17.0.20.1 | I9: ELIGIBLE | K9: Không | L9: ELIGIBLE | N9: 4f1514980495c4daaae2eb060228a87e14cbae11
A10: TheAlgorithms-Java-96c1a96647c9_d6010e87bc39890f | B10: TheAlgorithms/Java | C10: 96c1a96647c9 | D10: src/main/java/com/thealgorithms/maths/FindMax.java | E10: src/test/java/com/thealgorithms/maths/FindMaxTest.java | F10: maven | G10: junit5 | H10: 17.0.20.1 | I10: ELIGIBLE | K10: Không | L10: ELIGIBLE | N10: 96c1a96647c947f8f0c531ade3bc18967359e0ea
A11: TheAlgorithms-Java-a3a2d845d563_8bcf9c7af84d4406 | B11: TheAlgorithms/Java | C11: a3a2d845d563 | D11: src/main/java/com/thealgorithms/maths/Armstrong.java | E11: src/test/java/com/thealgorithms/maths/ArmstrongTest.java | F11: maven | G11: junit5 | H11: 17.0.20.1 | I11: ELIGIBLE | K11: Không | L11: ELIGIBLE | N11: a3a2d845d563a901946e052eeebba2f6e51e37d8
A12: TheAlgorithms-Java-e5c7a08874a6_0bc8a5a559202e54 | B12: TheAlgorithms/Java | C12: e5c7a08874a6 | D12: src/main/java/com/thealgorithms/others/StackPostfixNotation.java | E12: src/test/java/com/thealgorithms/others/StackPostfixNotationTest.java | F12: maven | G12: junit5 | H12: 17.0.20.1 | I12: ELIGIBLE | K12: Không | L12: ELIGIBLE | N12: e5c7a08874a6c7ff043ec5e3f44b3aac553f4e53
A13: YehiaFarghaly-database-engine-8314bfdec0aa_b11554464872b347 | B13: YehiaFarghaly/database-engine | C13: 8314bfdec0aa | D13: src/main/java/app/DBApp.java | E13: src/test/java/app/DBAppTest.java | F13: maven | G13: unknown | H13: 1.8.0_504 | I13: MAIN_BUILD_FAILED | J13: MAIN_BUILD_FAILED | K13: Có | L13: MAIN_BUILD_FAILED | M13: MAIN_BUILD_FAILED | N13: 8314bfdec0aa431561d903d788ecdf31fd3c6c5c
A14: YehiaFarghaly-database-engine-c5f961f27373_9f3ec66f97ec3328 | B14: YehiaFarghaly/database-engine | C14: c5f961f27373 | D14: src/main/java/app/DBApp.java | E14: src/test/java/app/DBAppTest.java | F14: maven | G14: unknown | H14: 1.8.0_504 | I14: MAIN_BUILD_FAILED | J14: MAIN_BUILD_FAILED | K14: Có | L14: MAIN_BUILD_FAILED | M14: MAIN_BUILD_FAILED | N14: c5f961f27373a552d506ba0380d3898188971523
A15: adoble-adr-j-7fe616c55a5b_ca0aaab55560f619 | B15: adoble/adr-j | C15: 7fe616c55a5b | D15: src/main/java/org/doble/commands/CommandNew.java | E15: src/test/java/org/doble/adr/CommandNewTest.java | F15: gradle | G15: junit5 | H15: 17.0.20.1 | I15: PROBE_FAILED | J15: PROBE_FAILED | K15: Có | L15: ELIGIBLE | N15: 7fe616c55a5b9d8c17f0e69a5aaf8daca9d78abd
A16: aws-aws-secretsmanager-jdbc-d25e52d637cf_19f0c78a9e45eb61 | B16: aws/aws-secretsmanager-jdbc | C16: d25e52d637cf | D16: src/main/java/com/amazonaws/secretsmanager/sql/AWSSecretsManagerPostgreSQLDriver.java | E16: src/test/java/com/amazonaws/secretsmanager/sql/AWSSecretsManagerPostgreSQLDriverTest.java | F16: maven | G16: junit4 | H16: 17.0.20.1 | I16: PROBE_FAILED | J16: PROBE_FAILED | K16: Có | L16: ELIGIBLE | N16: d25e52d637cff0b8fc971738d514522074ba4e6e
A17: awslabs-aws-java-nio-spi-for-s3-8ae86f85f328_8bdf6adfd7816b9f | B17: awslabs/aws-java-nio-spi-for-s3 | C17: 8ae86f85f328 | D17: src/main/java/software/amazon/nio/spi/s3/S3Path.java | E17: src/test/java/software/amazon/nio/spi/s3/S3PathTest.java | F17: gradle | G17: junit5 | H17: 11.0.32.1 | I17: MAIN_BUILD_FAILED | J17: MAIN_BUILD_FAILED | K17: Có | L17: ELIGIBLE | N17: 8ae86f85f32877e8eb8230582cae7a058b251879
A18: awslabs-aws-java-nio-spi-for-s3-ea1044d51bb4_c33aa3c891119328 | B18: awslabs/aws-java-nio-spi-for-s3 | C18: ea1044d51bb4 | D18: src/main/java/software/amazon/nio/spi/s3/S3FileSystem.java | E18: src/test/java/software/amazon/nio/spi/s3/S3FileSystemTest.java | F18: gradle | G18: junit4 | H18: 11.0.32.1 | I18: MAIN_BUILD_FAILED | J18: MAIN_BUILD_FAILED | K18: Có | L18: ELIGIBLE | N18: ea1044d51bb4f61af05b6651539a719b7a03c529
A19: ballerina-platform-lsp4intellij-8b03eddead47_8a41c5afa64da683 | B19: ballerina-platform/lsp4intellij | C19: 8b03eddead47 | D19: src/main/java/org/wso2/lsp4intellij/utils/FileUtils.java | E19: src/test/java/org/wso2/lsp4intellij/utils/FileUtilsTest.java | F19: gradle | G19: unknown | H19: 11.0.32.1 | I19: MAIN_BUILD_FAILED | J19: MAIN_BUILD_FAILED | K19: Có | L19: MAIN_BUILD_FAILED | M19: MAIN_BUILD_FAILED | N19: 8b03eddead47f04da18c51534a558654206eeae6
A20: beanshell-beanshell-7a60a06bb567_1dd7dd63d2396c0b | B20: beanshell/beanshell | C20: 7a60a06bb567 | D20: src/main/java/bsh/Reflect.java | E20: src/test/java/bsh/ReflectTest.java | F20: maven | G20: unknown | H20: 17.0.20.1 | I20: JDK_UNSUPPORTED | J20: JDK_VERSION_MISMATCH | K20: Có | L20: JDK_UNSUPPORTED | M20: JDK_VERSION_MISMATCH | N20: 7a60a06bb56774d1f6b1188ee66e712073b90a81
A21: c-rack-cbor-java-cabd70d02e86_d1a64497137640e8 | B21: c-rack/cbor-java | C21: cabd70d02e86 | D21: src/main/java/co/nstant/in/cbor/decoder/SpecialDecoder.java | E21: src/test/java/co/nstant/in/cbor/decoder/SpecialDecoderTest.java | F21: maven | G21: junit4 | H21: 17.0.20.1 | I21: PROBE_FAILED | J21: PROBE_FAILED | K21: Có | L21: ELIGIBLE | N21: cabd70d02e864354117d73d96d70ab021d748188
A22: c-rack-cbor-java-cabd70d02e86_6636a0955048234f | B22: c-rack/cbor-java | C22: cabd70d02e86 | D22: src/main/java/co/nstant/in/cbor/encoder/SpecialEncoder.java | E22: src/test/java/co/nstant/in/cbor/encoder/SpecialEncoderTest.java | F22: maven | G22: junit4 | H22: 17.0.20.1 | I22: PROBE_FAILED | J22: PROBE_FAILED | K22: Có | L22: ELIGIBLE | N22: cabd70d02e864354117d73d96d70ab021d748188
A23: c-rack-cbor-java-cabd70d02e86_43dd6205480b0547 | B23: c-rack/cbor-java | C23: cabd70d02e86 | D23: src/main/java/co/nstant/in/cbor/model/SpecialType.java | E23: src/test/java/co/nstant/in/cbor/model/SpecialTypeTest.java | F23: maven | G23: unknown | H23: 17.0.20.1 | I23: EXCLUDED | J23: EXCLUDE_STRICT_COHORT | K23: Không | L23: EXCLUDED | M23: EXCLUDE_STRICT_COHORT | N23: cabd70d02e864354117d73d96d70ab021d748188
A24: crawler-commons-crawler-commons-2c2cb3bf7a95_5e2d323552471b2b | B24: crawler-commons/crawler-commons | C24: 2c2cb3bf7a95 | D24: src/main/java/crawlercommons/robots/SimpleRobotRulesParser.java | E24: src/test/java/crawlercommons/robots/SimpleRobotRulesParserTest.java | F24: maven | G24: junit5 | H24: 11.0.32.1 | I24: ELIGIBLE | K24: Không | L24: ELIGIBLE | N24: 2c2cb3bf7a95c9dde49f8f9b93abc858b8c9311f
A25: damianszczepanik-cucumber-reporting-f11e9867941b_3f13eaf0743b8c46 | B25: damianszczepanik/cucumber-reporting | C25: f11e9867941b | D25: src/main/java/net/masterthought/cucumber/generators/FeatureReportPage.java | E25: src/test/java/net/masterthought/cucumber/generators/FeatureReportPageTest.java | F25: maven | G25: junit4 | H25: 17.0.20.1 | I25: ELIGIBLE | K25: Không | L25: ELIGIBLE | N25: f11e9867941b79e8fc3ba36570018bb6a70ac278
A26: davidmoten-openapi-to-plantuml-773340861981_3e30f317c010d2cd | B26: davidmoten/openapi-to-plantuml | C26: 773340861981 | D26: src/main/java/com/github/davidmoten/oas3/puml/Converter.java | E26: src/test/java/com/github/davidmoten/oas3/puml/ConverterTest.java | F26: maven | G26: junit4 | H26: 1.8.0_504 | I26: PROBE_FAILED | J26: PROBE_FAILED | K26: Có | L26: ELIGIBLE | N26: 77334086198150825c3eefd7118c0b75ceaa0366
A27: davidmoten-word-wrap-e59eedf0bac7_ad28b7ea2bd685d9 | B27: davidmoten/word-wrap | C27: e59eedf0bac7 | D27: src/main/java/org/davidmoten/text/utils/WordWrap.java | E27: src/test/java/org/davidmoten/text/utils/WordWrapTest.java | F27: maven | G27: junit4 | H27: 1.8.0_504 | I27: PROBE_FAILED | J27: PROBE_FAILED | K27: Có | L27: ELIGIBLE | N27: e59eedf0bac7d5ca7ee0062f3816c7ac5c3de4e0
A28: dmak-jaxb-xew-plugin-f48935133d6a_2f69feafb9a30f41 | B28: dmak/jaxb-xew-plugin | C28: f48935133d6a | D28: src/main/java/com/sun/tools/xjc/addon/xew/XmlElementWrapperPlugin.java | E28: src/test/java/com/sun/tools/xjc/addon/xew/XmlElementWrapperPluginTest.java | F28: maven | G28: unknown | H28: 1.8.0_504 | I28: EXCLUDED | J28: EXCLUDE_GENERATED_SOURCE | K28: Không | L28: EXCLUDED | M28: EXCLUDE_GENERATED_SOURCE | N28: f48935133d6ad30ad31613fca3b64db50f77fd26
A29: fishercoder1534-Leetcode-2110c6b023b7_66e7bdeab43f6856 | B29: fishercoder1534/Leetcode | C29: 2110c6b023b7 | D29: src/main/java/com/fishercoder/solutions/_235.java | E29: src/test/java/com/fishercoder/_235Test.java | F29: gradle | G29: junit4 | H29: 1.8.0_504 | I29: ELIGIBLE | K29: Không | L29: ELIGIBLE | N29: 2110c6b023b7c5623b2603dae9979201f2b2c3ac
A30: fusesource-jansi-58260c6ce08c_1b5d70b5213f1515 | B30: fusesource/jansi | C30: 58260c6ce08c | D30: src/main/java/org/fusesource/jansi/AnsiRenderer.java | E30: src/test/java/org/fusesource/jansi/AnsiRendererTest.java | F30: maven | G30: junit5 | H30: 17.0.20.1 | I30: ELIGIBLE | K30: Không | L30: ELIGIBLE | N30: 58260c6ce08c203e342df7d221c9902ada230d8c
A31: gradle-common-custom-user-data-gradle-plugin-982c77984b5e_4d8fde5d5430d03e | B31: gradle/common-custom-user-data-gradle-plugin | C31: 982c77984b5e | D31: src/main/java/com/gradle/Utils.java | E31: src/test/java/com/gradle/UtilsTest.java | F31: gradle | G31: junit5 | H31: 17.0.20.1 | I31: ELIGIBLE | K31: Không | L31: ELIGIBLE | N31: 982c77984b5e263fe8abf40fb0b8ed7dfd0a5b82
A32: jhy-jsoup-0121311b1bd5_1b8051b85de3b685 | B32: jhy/jsoup | C32: 0121311b1bd5 | D32: src/main/java/org/jsoup/internal/StringUtil.java | E32: src/test/java/org/jsoup/internal/StringUtilTest.java | F32: maven | G32: junit5 | H32: 17.0.20.1 | I32: PROBE_FAILED | J32: PROBE_FAILED | K32: Có | L32: ELIGIBLE | N32: 0121311b1bd56cbbd29e9b291d42564d5135afa5
A33: jhy-jsoup-111919256590_b89b6bda70f141c8 | B33: jhy/jsoup | C33: 111919256590 | D33: src/main/java/org/jsoup/nodes/Element.java | E33: src/test/java/org/jsoup/nodes/ElementTest.java | F33: maven | G33: junit5 | H33: 17.0.20.1 | I33: ELIGIBLE | K33: Không | L33: ELIGIBLE | N33: 111919256590a37b74d2caa119c4965d1a25124a
A34: jhy-jsoup-195f484ba5de_13882c16ce943ea0 | B34: jhy/jsoup | C34: 195f484ba5de | D34: src/main/java/org/jsoup/parser/Tag.java | E34: src/test/java/org/jsoup/parser/TagTest.java | F34: maven | G34: junit5 | H34: 17.0.20.1 | I34: ELIGIBLE | K34: Không | L34: ELIGIBLE | N34: 195f484ba5de224a3c1be6086e8c0dab066557d9
A35: jhy-jsoup-220a3b21be3b_481eb329450a394c | B35: jhy/jsoup | C35: 220a3b21be3b | D35: src/main/java/org/jsoup/parser/HtmlTreeBuilder.java | E35: src/test/java/org/jsoup/parser/HtmlTreeBuilderTest.java | F35: maven | G35: junit5 | H35: 17.0.20.1 | I35: ELIGIBLE | K35: Không | L35: ELIGIBLE | N35: 220a3b21be3b3d50ed90f5665aff031a989572f4
A36: jhy-jsoup-220a3b21be3b_a0b8bfff46f20a59 | B36: jhy/jsoup | C36: 220a3b21be3b | D36: src/main/java/org/jsoup/parser/HtmlTreeBuilderState.java | E36: src/test/java/org/jsoup/parser/HtmlTreeBuilderStateTest.java | F36: maven | G36: unknown | H36: 17.0.20.1 | I36: EXCLUDED | J36: EXCLUDE_STRICT_COHORT | K36: Không | L36: EXCLUDED | M36: EXCLUDE_STRICT_COHORT | N36: 220a3b21be3b3d50ed90f5665aff031a989572f4
A37: jhy-jsoup-29be991198d3_f461279a50689ad0 | B37: jhy/jsoup | C37: 29be991198d3 | D37: src/main/java/org/jsoup/nodes/TextNode.java | E37: src/test/java/org/jsoup/nodes/TextNodeTest.java | F37: maven | G37: junit5 | H37: 17.0.20.1 | I37: ELIGIBLE | K37: Không | L37: ELIGIBLE | N37: 29be991198d3b518d64ee36176ae415688468f61
A38: jhy-jsoup-2f48a617fe48_5117e12bab8e7710 | B38: jhy/jsoup | C38: 2f48a617fe48 | D38: src/main/java/org/jsoup/nodes/Element.java | E38: src/test/java/org/jsoup/nodes/ElementTest.java | F38: maven | G38: junit5 | H38: 17.0.20.1 | I38: ELIGIBLE | K38: Không | L38: ELIGIBLE | N38: 2f48a617fe48262c0c688188345f73a0fbfe6e59
A39: jhy-jsoup-401c8b010e01_9f0ad5817e5c33b1 | B39: jhy/jsoup | C39: 401c8b010e01 | D39: src/main/java/org/jsoup/parser/HtmlTreeBuilder.java | E39: src/test/java/org/jsoup/parser/HtmlTreeBuilderTest.java | F39: maven | G39: junit5 | H39: 17.0.20.1 | I39: ELIGIBLE | K39: Không | L39: ELIGIBLE | N39: 401c8b010e01a03d5af00b88387e0dc3a8c1c8a4
A40: jhy-jsoup-45ed00232722_f0bba6b573e3cc1f | B40: jhy/jsoup | C40: 45ed00232722 | D40: src/main/java/org/jsoup/helper/HttpConnection.java | E40: src/test/java/org/jsoup/helper/HttpConnectionTest.java | F40: maven | G40: junit5 | H40: 17.0.20.1 | I40: PROBE_FAILED | J40: PROBE_FAILED | K40: Có | L40: ELIGIBLE | N40: 45ed00232722efacafdf58cb0e2bdcc751585f84
...

Sheet Loại trước preflight
A1: Repository | B1: Bug (commit đã fix) | C1: File trong bug_patch | D1: Lý do loại | E1: Giải thích
A2: aws/event-ruler | B2: 68481127e050 | C2: src/main/software/amazon/event/ruler/JsonRuleCompiler.java | D2: NOT_UNDER_SRC_MAIN_JAVA | E2: Mã nguồn không nằm trong src/main/java (bố cục thư mục không chuẩn)
A3: aws/event-ruler | B3: 68481127e050 | C3: src/main/software/amazon/event/ruler/RuleCompiler.java | D3: NOT_UNDER_SRC_MAIN_JAVA | E3: Mã nguồn không nằm trong src/main/java (bố cục thư mục không chuẩn)
A4: iipc/jwarc | B4: 6c7083b72172 | C4: src/org/netpreserve/jwarc/MessageParser.java | D4: NOT_UNDER_SRC_MAIN_JAVA | E4: Mã nguồn không nằm trong src/main/java (bố cục thư mục không chuẩn)
A5: iipc/jwarc | B5: 62dffb16a1a8 | C5: src/org/netpreserve/jwarc/WarcParser.java | D5: NOT_UNDER_SRC_MAIN_JAVA | E5: Mã nguồn không nằm trong src/main/java (bố cục thư mục không chuẩn)
A6: iipc/jwarc | B6: 6c7083b72172 | C6: src/org/netpreserve/jwarc/WarcParser.java | D6: NOT_UNDER_SRC_MAIN_JAVA | E6: Mã nguồn không nằm trong src/main/java (bố cục thư mục không chuẩn)
A7: iipc/jwarc | B7: 6c7083b72172 | C7: src/org/netpreserve/jwarc/WarcReader.java | D7: NOT_UNDER_SRC_MAIN_JAVA | E7: Mã nguồn không nằm trong src/main/java (bố cục thư mục không chuẩn)
A8: iipc/jwarc | B8: e00ce46c1e36 | C8: src/org/netpreserve/jwarc/cdx/CdxRequestEncoder.java | D8: NOT_UNDER_SRC_MAIN_JAVA | E8: Mã nguồn không nằm trong src/main/java (bố cục thư mục không chuẩn)
A9: iipc/jwarc | B9: d47a479c9025 | C9: src/org/netpreserve/jwarc/cdx/CdxRequestEncoder.java | D9: NOT_UNDER_SRC_MAIN_JAVA | E9: Mã nguồn không nằm trong src/main/java (bố cục thư mục không chuẩn)
A10: iipc/jwarc | B10: 6c7083b72172 | C10: src/org/netpreserve/jwarc/cdx/CdxWriter.java | D10: NOT_UNDER_SRC_MAIN_JAVA | E10: Mã nguồn không nằm trong src/main/java (bố cục thư mục không chuẩn)
A11: Bindambc/whatsapp-business-java-api | B11: 362caf5eb33c | C11: src/main/java/com/whatsapp/api/domain/messages/Language.java | D11: NO_PAIRED_TEST | E11: Không có test người viết tên <Tên>Test, Test<Tên>, <Tên>Tests trong module (quy tắc bắt buộc có test ghép, chốt 11/10/2026)
A12: Bindambc/whatsapp-business-java-api | B12: fd321cb63437 | C12: src/main/java/com/whatsapp/api/domain/templates/QuickReplyButton.java | D12: NO_PAIRED_TEST | E12: Không có test người viết tên <Tên>Test, Test<Tên>, <Tên>Tests trong module (quy tắc bắt buộc có test ghép, chốt 11/10/2026)
... A93: xtremexp/UT4X-Converter | B93: e16bad18b562 | C93: src/main/java/org/xtx/ut4converter/t3d/T3DSimpleProperty.java | D93: NO_PAIRED_TEST | E93: Không có test người viết tên <Tên>Test, Test<Tên>, <Tên>Tests trong module (quy tắc bắt buộc có test ghép, chốt 11/10/2026)

Sheet Repository
A1: Repository | B1: CUT ứng viên | C1: ELIGIBLE lần 1 | D1: ELIGIBLE sau chạy lại | E1: Số bug có CUT ELIGIBLE | F1: Vào tập đánh giá? | G1: Có bug dư cho pilot?
A2: AuthMe/ConfigMe | B2: =COUNTIF('Chi tiết CUT'!$B$2:$B$181,A2) -> 2 | C2: =COUNTIFS('Chi tiết CUT'!$B$2:$B$181,A2,'Chi tiết CUT'!$I$2:$I$181,"ELIGIBLE") -> 2 | D2: =COUNTIFS('Chi tiết CUT'!$B$2:$B$181,A2,'Chi tiết CUT'!$L$2:$L$181,"ELIGIBLE") -> 2 | E2: =SUMPRODUCT(('Chi tiết CUT'!$B$2:$B$181=A2)*('Chi tiết CUT'!$L$2:$L$181="ELIGIBLE")/COUNTIFS('Chi tiết CUT'!$B$2:$B$181,'Chi tiết CUT'!$B$2:$B$181,'Chi tiết CUT'!$C$2:$C$181,'Chi tiết CUT'!$C$2:$C$181,'Chi tiết CUT'!$L$2:$L$181,'Chi tiết CUT'!$L$2:$L$181)) -> 2 | F2: =IF(D2>0,"Có","Không") -> Có | G2: =IF(E2>=2,"Có","Không") -> Có
A3: BrightSpots/rcv | B3: =COUNTIF('Chi tiết CUT'!$B$2:$B$181,A3) -> 1 | C3: =COUNTIFS('Chi tiết CUT'!$B$2:$B$181,A3,'Chi tiết CUT'!$I$2:$I$181,"ELIGIBLE") -> 0 | D3: =COUNTIFS('Chi tiết CUT'!$B$2:$B$181,A3,'Chi tiết CUT'!$L$2:$L$181,"ELIGIBLE") -> 0 | E3: =SUMPRODUCT(('Chi tiết CUT'!$B$2:$B$181=A3)*('Chi tiết CUT'!$L$2:$L$181="ELIGIBLE")/COUNTIFS('Chi tiết CUT'!$B$2:$B$181,'Chi tiết CUT'!$B$2:$B$181,'Chi tiết CUT'!$C$2:$C$181,'Chi tiết CUT'!$C$2:$C$181,'Chi tiết CUT'!$L$2:$L$181,'Chi tiết CUT'!$L$2:$L$181)) -> 0 | F3: =IF(D3>0,"Có","Không") -> Không | G3: =IF(E3>=2,"Có","Không") -> Không
A4: Enigmatis/graphql-java-annotations | B4: =COUNTIF('Chi tiết CUT'!$B$2:$B$181,A4) -> 1 | C4: =COUNTIFS('Chi tiết CUT'!$B$2:$B$181,A4,'Chi tiết CUT'!$I$2:$I$181,"ELIGIBLE") -> 0 | D4: =COUNTIFS('Chi tiết CUT'!$B$2:$B$181,A4,'Chi tiết CUT'!$L$2:$L$181,"ELIGIBLE") -> 0 | E4: =SUMPRODUCT(('Chi tiết CUT'!$B$2:$B$181=A4)*('Chi tiết CUT'!$L$2:$L$181="ELIGIBLE")/COUNTIFS('Chi tiết CUT'!$B$2:$B$181,'Chi tiết CUT'!$B$2:$B$181,'Chi tiết CUT'!$C$2:$C$181,'Chi tiết CUT'!$C$2:$C$181,'Chi tiết CUT'!$L$2:$L$181,'Chi tiết CUT'!$L$2:$L$181)) -> 0 | F4: =IF(D4>0,"Có","Không") -> Không | G4: =IF(E4>=2,"Có","Không") -> Không
A5: GoSimpleLLC/nbvcxz | B5: =COUNTIF('Chi tiết CUT'!$B$2:$B$181,A5) -> 1 | C5: =COUNTIFS('Chi tiết CUT'!$B$2:$B$181,A5,'Chi tiết CUT'!$I$2:$I$181,"ELIGIBLE") -> 1 | D5: =COUNTIFS('Chi tiết CUT'!$B$2:$B$181,A5,'Chi tiết CUT'!$L$2:$L$181,"ELIGIBLE") -> 1 | E5: =SUMPRODUCT(('Chi tiết CUT'!$B$2:$B$181=A5)*('Chi tiết CUT'!$L$2:$L$181="ELIGIBLE")/COUNTIFS('Chi tiết CUT'!$B$2:$B$181,'Chi tiết CUT'!$B$2:$B$181,'Chi tiết CUT'!$C$2:$C$181,'Chi tiết CUT'!$C$2:$C$181,'Chi tiết CUT'!$L$2:$L$181,'Chi tiết CUT'!$L$2:$L$181)) -> 1 | F5: =IF(D5>0,"Có","Không") -> Có | G5: =IF(E5>=2,"Có","Không") -> Không
A6: LMAX-Exchange/Simple-DSL | B6: =COUNTIF('Chi tiết CUT'!$B$2:$B$181,A6) -> 2 | C6: =COUNTIFS('Chi tiết CUT'!$B$2:$B$181,A6,'Chi tiết CUT'!$I$2:$I$181,"ELIGIBLE") -> 2 | D6: =COUNTIFS('Chi tiết CUT'!$B$2:$B$181,A6,'Chi tiết CUT'!$L$2:$L$181,"ELIGIBLE") -> 2 | E6: =SUMPRODUCT(('Chi tiết CUT'!$B$2:$B$181=A6)*('Chi tiết CUT'!$L$2:$L$181="ELIGIBLE")/COUNTIFS('Chi tiết CUT'!$B$2:$B$181,'Chi tiết CUT'!$B$2:$B$181,'Chi tiết CUT'!$C$2:$C$181,'Chi tiết CUT'!$C$2:$C$181,'Chi tiết CUT'!$L$2:$L$181,'Chi tiết CUT'!$L$2:$L$181)) -> 2 | F6: =IF(D6>0,"Có","Không") -> Có | G6: =IF(E6>=2,"Có","Không") -> Có
A7: TheAlgorithms/Java | B7: =COUNTIF('Chi tiết CUT'!$B$2:$B$181,A7) -> 4 | C7: =COUNTIFS('Chi tiết CUT'!$B$2:$B$181,A7,'Chi tiết CUT'!$I$2:$I$181,"ELIGIBLE") -> 4 | D7: =COUNTIFS('Chi tiết CUT'!$B$2:$B$181,A7,'Chi tiết CUT'!$L$2:$L$181,"ELIGIBLE") -> 4 | E7: =SUMPRODUCT(('Chi tiết CUT'!$B$2:$B$181=A7)*('Chi tiết CUT'!$L$2:$L$181="ELIGIBLE")/COUNTIFS('Chi tiết CUT'!$B$2:$B$181,'Chi tiết CUT'!$B$2:$B$181,'Chi tiết CUT'!$C$2:$C$181,'Chi tiết CUT'!$C$2:$C$181,'Chi tiết CUT'!$L$2:$L$181,'Chi tiết CUT'!$L$2:$L$181)) -> 4 | F7: =IF(D7>0,"Có","Không") -> Có | G7: =IF(E7>=2,"Có","Không") -> Có
A8: YehiaFarghaly/database-engine | B8: =COUNTIF('Chi tiết CUT'!$B$2:$B$181,A8) -> 2 | C8: =COUNTIFS('Chi tiết CUT'!$B$2:$B$181,A8,'Chi tiết CUT'!$I$2:$I$181,"ELIGIBLE") -> 0 | D8: =COUNTIFS('Chi tiết CUT'!$B$2:$B$181,A8,'Chi tiết CUT'!$L$2:$L$181,"ELIGIBLE") -> 0 | E8: =SUMPRODUCT(('Chi tiết CUT'!$B$2:$B$181=A8)*('Chi tiết CUT'!$L$2:$L$181="ELIGIBLE")/COUNTIFS('Chi tiết CUT'!$B$2:$B$181,'Chi tiết CUT'!$B$2:$B$181,'Chi tiết CUT'!$C$2:$C$181,'Chi tiết CUT'!$C$2:$C$181,'Chi tiết CUT'!$L$2:$L$181,'Chi tiết CUT'!$L$2:$L$181)) -> 0 | F8: =IF(D8>0,"Có","Không") -> Không | G8: =IF(E8>=2,"Có","Không") -> Không
A9: adoble/adr-j | B9: =COUNTIF('Chi tiết CUT'!$B$2:$B$181,A9) -> 1 | C9: =COUNTIFS('Chi tiết CUT'!$B$2:$B$181,A9,'Chi tiết CUT'!$I$2:$I$181,"ELIGIBLE") -> 0 | D9: =COUNTIFS('Chi tiết CUT'!$B$2:$B$181,A9,'Chi tiết CUT'!$L$2:$L$181,"ELIGIBLE") -> 1 | E9: =SUMPRODUCT(('Chi tiết CUT'!$B$2:$B$181=A9)*('Chi tiết CUT'!$L$2:$L$181="ELIGIBLE")/COUNTIFS('Chi tiết CUT'!$B$2:$B$181,'Chi tiết CUT'!$B$2:$B$181,'Chi tiết CUT'!$C$2:$C$181,'Chi tiết CUT'!$C$2:$C$181,'Chi tiết CUT'!$L$2:$L$181,'Chi tiết CUT'!$L$2:$L$181)) -> 1 | F9: =IF(D9>0,"Có","Không") -> Có | G9: =IF(E9>=2,"Có","Không") -> Không
A10: aws/aws-secretsmanager-jdbc | B10: =COUNTIF('Chi tiết CUT'!$B$2:$B$181,A10) -> 1 | C10: =COUNTIFS('Chi tiết CUT'!$B$2:$B$181,A10,'Chi tiết CUT'!$I$2:$I$181,"ELIGIBLE") -> 0 | D10: =COUNTIFS('Chi tiết CUT'!$B$2:$B$181,A10,'Chi tiết CUT'!$L$2:$L$181,"ELIGIBLE") -> 1 | E10: =SUMPRODUCT(('Chi tiết CUT'!$B$2:$B$181=A10)*('Chi tiết CUT'!$L$2:$L$181="ELIGIBLE")/COUNTIFS('Chi tiết CUT'!$B$2:$B$181,'Chi tiết CUT'!$B$2:$B$181,'Chi tiết CUT'!$C$2:$C$181,'Chi tiết CUT'!$C$2:$C$181,'Chi tiết CUT'!$L$2:$L$181,'Chi tiết CUT'!$L$2:$L$181)) -> 1 | F10: =IF(D10>0,"Có","Không") -> Có | G10: =IF(E10>=2,"Có","Không") -> Không
A11: awslabs/aws-java-nio-spi-for-s3 | B11: =COUNTIF('Chi tiết CUT'!$B$2:$B$181,A11) -> 2 | C11: =COUNTIFS('Chi tiết CUT'!$B$2:$B$181,A11,'Chi tiết CUT'!$I$2:$I$181,"ELIGIBLE") -> 0 | D11: =COUNTIFS('Chi tiết CUT'!$B$2:$B$181,A11,'Chi tiết CUT'!$L$2:$L$181,"ELIGIBLE") -> 2 | E11: =SUMPRODUCT(('Chi tiết CUT'!$B$2:$B$181=A11)*('Chi tiết CUT'!$L$2:$L$181="ELIGIBLE")/COUNTIFS('Chi tiết CUT'!$B$2:$B$181,'Chi tiết CUT'!$B$2:$B$181,'Chi tiết CUT'!$C$2:$C$181,'Chi tiết CUT'!$C$2:$C$181,'Chi tiết CUT'!$L$2:$L$181,'Chi tiết CUT'!$L$2:$L$181)) -> 2 | F11: =IF(D11>0,"Có","Không") -> Có | G11: =IF(E11>=2,"Có","Không") -> Có
A12: ballerina-platform/lsp4intellij | B12: =COUNTIF('Chi tiết CUT'!$B$2:$B$181,A12) -> 1 | C12: =COUNTIFS('Chi tiết CUT'!$B$2:$B$181,A12,'Chi tiết CUT'!$I$2:$I$181,"ELIGIBLE") -> 0 | D12: =COUNTIFS('Chi tiết CUT'!$B$2:$B$181,A12,'Chi tiết CUT'!$L$2:$L$181,"ELIGIBLE") -> 0 | E12: =SUMPRODUCT(('Chi tiết CUT'!$B$2:$B$181=A12)*('Chi tiết CUT'!$L$2:$L$181="ELIGIBLE")/COUNTIFS('Chi tiết CUT'!$B$2:$B$181,'Chi tiết CUT'!$B$2:$B$181,'Chi tiết CUT'!$C$2:$C$181,'Chi tiết CUT'!$C$2:$C$181,'Chi tiết CUT'!$L$2:$L$181,'Chi tiết CUT'!$L$2:$L$181)) -> 0 | F12: =IF(D12>0,"Có","Không") -> Không | G12: =IF(E12>=2,"Có","Không") -> Không
A13: beanshell/beanshell | B13: =COUNTIF('Chi tiết CUT'!$B$2:$B$181,A13) -> 1 | C13: =COUNTIFS('Chi tiết CUT'!$B$2:$B$181,A13,'Chi tiết CUT'!$I$2:$I$181,"ELIGIBLE") -> 0 | D13: =COUNTIFS('Chi tiết CUT'!$B$2:$B$181,A13,'Chi tiết CUT'!$L$2:$L$181,"ELIGIBLE") -> 0 | E13: =SUMPRODUCT(('Chi tiết CUT'!$B$2:$B$181=A13)*('Chi tiết CUT'!$L$2:$L$181="ELIGIBLE")/COUNTIFS('Chi tiết CUT'!$B$2:$B$181,'Chi tiết CUT'!$B$2:$B$181,'Chi tiết CUT'!$C$2:$C$181,'Chi tiết CUT'!$C$2:$C$181,'Chi tiết CUT'!$L$2:$L$181,'Chi tiết CUT'!$L$2:$L$181)) -> 0 | F13: =IF(D13>0,"Có","Không") -> Không | G13: =IF(E13>=2,"Có","Không") -> Không
... A36: xtremexp/UT4X-Converter | B36: =COUNTIF('Chi tiết CUT'!$B$2:$B$181,A36) -> 1 | C36: =COUNTIFS('Chi tiết CUT'!$B$2:$B$181,A36,'Chi tiết CUT'!$I$2:$I$181,"ELIGIBLE") -> 0 | D36: =COUNTIFS('Chi tiết CUT'!$B$2:$B$181,A36,'Chi tiết CUT'!$L$2:$L$181,"ELIGIBLE") -> 0 | E36: =SUMPRODUCT(('Chi tiết CUT'!$B$2:$B$181=A36)*('Chi tiết CUT'!$L$2:$L$181="ELIGIBLE")/COUNTIFS('Chi tiết CUT'!$B$2:$B$181,'Chi tiết CUT'!$B$2:$B$181,'Chi tiết CUT'!$C$2:$C$181,'Chi tiết CUT'!$C$2:$C$181,'Chi tiết CUT'!$L$2:$L$181,'Chi tiết CUT'!$L$2:$L$181)) -> 0 | F36: =IF(D36>0,"Có","Không") -> Không | G36: =IF(E36>=2,"Có","Không") -> Không
A37: Tổng | B37: =SUM(B2:B36) -> 180 | C37: =SUM(C2:C36) -> 96 | D37: =SUM(D2:D36) -> 152 | E37: =SUM(E2:E36) -> 135 | F37: =COUNTIF(F2:F36,"Có") -> 25 | G37: =COUNTIF(G2:G36,"Có") -> 8

Sheet Trạng thái
A1: Trạng thái preflight | B1: Lần 1 | C1: Sau chạy lại | D1: Thay đổi | E1: Ý nghĩa / nguyên nhân chính
A2: ELIGIBLE | B2: =COUNTIF('Chi tiết CUT'!$I$2:$I$181,A2) -> 96 | C2: =COUNTIF('Chi tiết CUT'!$L$2:$L$181,A2) -> 152 | D2: =C2-B2 -> 56 | E2: Qua đủ các bước: checkout, build main, build test, phân tích AST, compile probe
A3: PROBE_FAILED | B3: =COUNTIF('Chi tiết CUT'!$I$2:$I$181,A3) -> 55 | C3: =COUNTIF('Chi tiết CUT'!$L$2:$L$181,A3) -> 1 | D3: =C3-B3 -> -54 | E3: Lần 1: 55 ca do file probe của công cụ (thiếu throws, null mơ hồ, plugin format). Còn 1 ca: spring-javaformat 0.0.31 không nhận cờ skip
A4: EXCLUDED | B4: =COUNTIF('Chi tiết CUT'!$I$2:$I$181,A4) -> 13 | C4: =COUNTIF('Chi tiết CUT'!$L$2:$L$181,A4) -> 13 | D4: =C4-B4 -> 0 | E4: Loại theo chính sách: enum/record, abstract class, mã sinh tự động, class lồng
A5: MAIN_BUILD_FAILED | B5: =COUNTIF('Chi tiết CUT'!$I$2:$I$181,A5) -> 5 | C5: =COUNTIF('Chi tiết CUT'!$L$2:$L$181,A5) -> 3 | D5: =C5-B5 -> -2 | E5: Build mã production thất bại; lần 1 có aws-java-nio-spi-for-s3 do chọn JDK 8 cho project dùng --release
A6: DEPENDENCY_UNAVAILABLE | B6: =COUNTIF('Chi tiết CUT'!$I$2:$I$181,A6) -> 3 | C6: =COUNTIF('Chi tiết CUT'!$L$2:$L$181,A6) -> 3 | D6: =C6-B6 -> 0 | E6: Không tải được dependency
A7: JDK_UNSUPPORTED | B7: =COUNTIF('Chi tiết CUT'!$I$2:$I$181,A7) -> 3 | C7: =COUNTIF('Chi tiết CUT'!$L$2:$L$181,A7) -> 3 | D7: =C7-B7 -> 0 | E7: Phiên bản JDK yêu cầu không khớp hoặc không có
A8: TEST_COMPILE_FAILED | B8: =COUNTIF('Chi tiết CUT'!$I$2:$I$181,A8) -> 3 | C8: =COUNTIF('Chi tiết CUT'!$L$2:$L$181,A8) -> 3 | D8: =C8-B8 -> 0 | E8: Test sẵn có của repository không compile được
A9: BUILD_TIMEOUT | B9: =COUNTIF('Chi tiết CUT'!$I$2:$I$181,A9) -> 2 | C9: =COUNTIF('Chi tiết CUT'!$L$2:$L$181,A9) -> 2 | D9: =C9-B9 -> 0 | E9: Build vượt 900 giây
A10: Tổng | B10: =SUM(B2:B9) -> 180 | C10: =SUM(C2:C9) -> 180 | D10: =SUM(D2:D9) -> 0
